[2023-05-14 11:09:45,924] DEBUG [_ConfigReader.py root read_prop (13)]: twilio_to_num:to-number
[2023-05-14 11:09:45,924] DEBUG [_ConfigReader.py root read_prop (13)]: twilio_from_num:from-number
[2023-05-14 11:09:45,924] DEBUG [_ConfigReader.py root read_prop (13)]: twilio_account_sid:account-sid
[2023-05-14 11:09:45,924] DEBUG [_ConfigReader.py root read_prop (13)]: twilio_auth_token:auth-token
[2023-05-14 11:09:45,924] DEBUG [_ConfigReader.py root read_prop (13)]: twilio_url:twilio-url
[2023-05-14 11:09:45,924] DEBUG [_ConfigReader.py root read_bool_prop (18)]: twilio_sms_enabled:True
[2023-05-14 11:09:45,924] DEBUG [_ConfigReader.py root read_bool_prop (18)]: twilio_call_enabled:True
[2023-05-14 11:09:45,924] DEBUG [_ConfigReader.py root read_prop (13)]: chat_id:-12345678
[2023-05-14 11:09:45,924] DEBUG [_ConfigReader.py root read_prop (13)]: parse_mode:Markdown
[2023-05-14 11:09:45,924] DEBUG [_ConfigReader.py root read_prop (13)]: bot_token:98765432:ABCdeFghIjkLMnoPQRSTuv123456789
[2023-05-14 11:09:45,925] DEBUG [_ConfigReader.py root read_prop (13)]: use_telegram:True
[2023-05-14 11:09:45,925] DEBUG [_ConfigReader.py root read_prop (13)]: use_twilio:False
[2023-05-14 11:09:45,925] DEBUG [_VfsClient.py root __init__ (25)]: Will use Telegram : True
[2023-05-14 11:09:45,925] DEBUG [_VfsClient.py root __init__ (26)]: Will use Twilio : False
[2023-05-14 11:09:45,925] DEBUG [_ConfigReader.py root read_prop (13)]: interval:120
[2023-05-14 11:09:45,925] DEBUG [vfs_appointment_bot.py __main__ <module> (37)]: Interval: 120
[2023-05-14 11:09:45,925] INFO [vfs_appointment_bot.py __main__ <module> (41)]: Starting VFS Appointment Bot
[2023-05-14 11:09:45,925] INFO [vfs_appointment_bot.py __main__ <module> (44)]: Running VFS Appointment Bot: Attempt#1
[2023-05-14 11:09:45,926] INFO [vfs_appointment_bot.py __main__ <module> (49)]: 'geckodriver' executable needs to be in PATH. . Please check the logs for more details
[2023-05-14 11:09:45,927] DEBUG [vfs_appointment_bot.py __main__ <module> (50)]: Message: 'geckodriver' executable needs to be in PATH. 
Traceback (most recent call last):
  File "/Users/kennethyellow/Documents/yellow/vfs-appointment-bot/venv/lib/python3.9/site-packages/selenium/webdriver/common/service.py", line 72, in start
    self.process = subprocess.Popen(cmd, env=self.env,
  File "/Library/Developer/CommandLineTools/Library/Frameworks/Python3.framework/Versions/3.9/lib/python3.9/subprocess.py", line 951, in __init__
    self._execute_child(args, executable, preexec_fn, close_fds,
  File "/Library/Developer/CommandLineTools/Library/Frameworks/Python3.framework/Versions/3.9/lib/python3.9/subprocess.py", line 1821, in _execute_child
    raise child_exception_type(errno_num, err_msg, err_filename)
FileNotFoundError: [Errno 2] No such file or directory: '../geckodriver'

During handling of the above exception, another exception occurred:

Traceback (most recent call last):
  File "/Users/kennethyellow/Documents/yellow/vfs-appointment-bot/vfs_appointment_bot/vfs_appointment_bot.py", line 45, in <module>
    _vfs_client.check_slot(visa_centre=visa_centre, category=category, sub_category=sub_category)
  File "/Users/kennethyellow/Documents/yellow/vfs-appointment-bot/vfs_appointment_bot/_VfsClient.py", line 144, in check_slot
    self._init_web_driver()
  File "/Users/kennethyellow/Documents/yellow/vfs-appointment-bot/vfs_appointment_bot/_VfsClient.py", line 42, in _init_web_driver
    self._web_driver = webdriver.Firefox(options=firefox_options, executable_path="../geckodriver")
  File "/Users/kennethyellow/Documents/yellow/vfs-appointment-bot/venv/lib/python3.9/site-packages/selenium/webdriver/firefox/webdriver.py", line 164, in __init__
    self.service.start()
  File "/Users/kennethyellow/Documents/yellow/vfs-appointment-bot/venv/lib/python3.9/site-packages/selenium/webdriver/common/service.py", line 81, in start
    raise WebDriverException(
selenium.common.exceptions.WebDriverException: Message: 'geckodriver' executable needs to be in PATH. 
Stack (most recent call last):
  File "/Users/kennethyellow/Documents/yellow/vfs-appointment-bot/vfs_appointment_bot/vfs_appointment_bot.py", line 50, in <module>
    logging.debug(e, exc_info=True, stack_info=True)
[2023-05-14 11:10:57,446] DEBUG [_ConfigReader.py root read_prop (13)]: twilio_to_num:to-number
[2023-05-14 11:10:57,446] DEBUG [_ConfigReader.py root read_prop (13)]: twilio_from_num:from-number
[2023-05-14 11:10:57,446] DEBUG [_ConfigReader.py root read_prop (13)]: twilio_account_sid:account-sid
[2023-05-14 11:10:57,446] DEBUG [_ConfigReader.py root read_prop (13)]: twilio_auth_token:auth-token
[2023-05-14 11:10:57,446] DEBUG [_ConfigReader.py root read_prop (13)]: twilio_url:twilio-url
[2023-05-14 11:10:57,446] DEBUG [_ConfigReader.py root read_bool_prop (18)]: twilio_sms_enabled:True
[2023-05-14 11:10:57,446] DEBUG [_ConfigReader.py root read_bool_prop (18)]: twilio_call_enabled:True
[2023-05-14 11:10:57,446] DEBUG [_ConfigReader.py root read_prop (13)]: chat_id:-12345678
[2023-05-14 11:10:57,446] DEBUG [_ConfigReader.py root read_prop (13)]: parse_mode:Markdown
[2023-05-14 11:10:57,447] DEBUG [_ConfigReader.py root read_prop (13)]: bot_token:98765432:ABCdeFghIjkLMnoPQRSTuv123456789
[2023-05-14 11:10:57,447] DEBUG [_ConfigReader.py root read_prop (13)]: use_telegram:True
[2023-05-14 11:10:57,447] DEBUG [_ConfigReader.py root read_prop (13)]: use_twilio:False
[2023-05-14 11:10:57,447] DEBUG [_VfsClient.py root __init__ (25)]: Will use Telegram : True
[2023-05-14 11:10:57,447] DEBUG [_VfsClient.py root __init__ (26)]: Will use Twilio : False
[2023-05-14 11:10:57,447] DEBUG [_ConfigReader.py root read_prop (13)]: interval:120
[2023-05-14 11:10:57,447] DEBUG [vfs_appointment_bot.py __main__ <module> (37)]: Interval: 120
[2023-05-14 11:10:57,447] INFO [vfs_appointment_bot.py __main__ <module> (41)]: Starting VFS Appointment Bot
[2023-05-14 11:10:57,447] INFO [vfs_appointment_bot.py __main__ <module> (44)]: Running VFS Appointment Bot: Attempt#1
[2023-05-14 11:10:59,337] DEBUG [_ConfigReader.py root read_prop (13)]: vfs_login_url:https://visa.vfsglobal.com/ind/en/deu/login
[2023-05-14 11:11:00,125] DEBUG [_ConfigReader.py root read_prop (13)]: vfs_email:email-id
[2023-05-14 11:11:00,125] DEBUG [_ConfigReader.py root read_prop (13)]: vfs_password:password
[2023-05-14 11:11:00,125] DEBUG [_VfsClient.py root _login (54)]: Logging in with email: email-id
[2023-05-14 11:11:20,473] DEBUG [_VfsClient.py root _validate_login (77)]: Unable to login. VFS website is not responding
[2023-05-14 11:11:20,473] INFO [vfs_appointment_bot.py __main__ <module> (49)]: Unable to login. VFS website is not responding. Please check the logs for more details
[2023-05-14 11:11:20,474] DEBUG [vfs_appointment_bot.py __main__ <module> (50)]: Unable to login. VFS website is not responding
Traceback (most recent call last):
  File "/Users/kennethyellow/Documents/yellow/vfs-appointment-bot/vfs_appointment_bot/_VfsClient.py", line 70, in _validate_login
    _new_booking_button = self._web_driver.find_element_by_xpath("//section/div/div[2]/button/span")
  File "/Users/kennethyellow/Documents/yellow/vfs-appointment-bot/venv/lib/python3.9/site-packages/selenium/webdriver/remote/webdriver.py", line 394, in find_element_by_xpath
    return self.find_element(by=By.XPATH, value=xpath)
  File "/Users/kennethyellow/Documents/yellow/vfs-appointment-bot/venv/lib/python3.9/site-packages/selenium/webdriver/remote/webdriver.py", line 976, in find_element
    return self.execute(Command.FIND_ELEMENT, {
  File "/Users/kennethyellow/Documents/yellow/vfs-appointment-bot/venv/lib/python3.9/site-packages/selenium/webdriver/remote/webdriver.py", line 321, in execute
    self.error_handler.check_response(response)
  File "/Users/kennethyellow/Documents/yellow/vfs-appointment-bot/venv/lib/python3.9/site-packages/selenium/webdriver/remote/errorhandler.py", line 242, in check_response
    raise exception_class(message, screen, stacktrace)
selenium.common.exceptions.NoSuchElementException: Message: Unable to locate element: //section/div/div[2]/button/span


During handling of the above exception, another exception occurred:

Traceback (most recent call last):
  File "/Users/kennethyellow/Documents/yellow/vfs-appointment-bot/vfs_appointment_bot/vfs_appointment_bot.py", line 45, in <module>
    _vfs_client.check_slot(visa_centre=visa_centre, category=category, sub_category=sub_category)
  File "/Users/kennethyellow/Documents/yellow/vfs-appointment-bot/vfs_appointment_bot/_VfsClient.py", line 151, in check_slot
    self._validate_login()
  File "/Users/kennethyellow/Documents/yellow/vfs-appointment-bot/vfs_appointment_bot/_VfsClient.py", line 78, in _validate_login
    raise Exception("Unable to login. VFS website is not responding")
Exception: Unable to login. VFS website is not responding
Stack (most recent call last):
  File "/Users/kennethyellow/Documents/yellow/vfs-appointment-bot/vfs_appointment_bot/vfs_appointment_bot.py", line 50, in <module>
    logging.debug(e, exc_info=True, stack_info=True)
[2023-05-14 11:12:36,350] DEBUG [_ConfigReader.py root read_prop (13)]: twilio_to_num:to-number
[2023-05-14 11:12:36,350] DEBUG [_ConfigReader.py root read_prop (13)]: twilio_from_num:from-number
[2023-05-14 11:12:36,350] DEBUG [_ConfigReader.py root read_prop (13)]: twilio_account_sid:account-sid
[2023-05-14 11:12:36,350] DEBUG [_ConfigReader.py root read_prop (13)]: twilio_auth_token:auth-token
[2023-05-14 11:12:36,350] DEBUG [_ConfigReader.py root read_prop (13)]: twilio_url:twilio-url
[2023-05-14 11:12:36,350] DEBUG [_ConfigReader.py root read_bool_prop (18)]: twilio_sms_enabled:True
[2023-05-14 11:12:36,350] DEBUG [_ConfigReader.py root read_bool_prop (18)]: twilio_call_enabled:True
[2023-05-14 11:12:36,350] DEBUG [_ConfigReader.py root read_prop (13)]: chat_id:-1001941267897
[2023-05-14 11:12:36,350] DEBUG [_ConfigReader.py root read_prop (13)]: parse_mode:Markdown
[2023-05-14 11:12:36,350] DEBUG [_ConfigReader.py root read_prop (13)]: bot_token:6281742980:AAGIAXJlxLQhzvW4oveGtq9Y7bUxfXyf0Wc
[2023-05-14 11:12:36,350] DEBUG [_ConfigReader.py root read_prop (13)]: use_telegram:True
[2023-05-14 11:12:36,350] DEBUG [_ConfigReader.py root read_prop (13)]: use_twilio:False
[2023-05-14 11:12:36,350] DEBUG [_VfsClient.py root __init__ (25)]: Will use Telegram : True
[2023-05-14 11:12:36,350] DEBUG [_VfsClient.py root __init__ (26)]: Will use Twilio : False
[2023-05-14 11:12:36,351] DEBUG [_ConfigReader.py root read_prop (13)]: interval:120
[2023-05-14 11:12:36,351] DEBUG [vfs_appointment_bot.py __main__ <module> (37)]: Interval: 120
[2023-05-14 11:12:36,351] INFO [vfs_appointment_bot.py __main__ <module> (41)]: Starting VFS Appointment Bot
[2023-05-14 11:12:36,351] INFO [vfs_appointment_bot.py __main__ <module> (44)]: Running VFS Appointment Bot: Attempt#1
[2023-05-14 11:12:38,215] DEBUG [_ConfigReader.py root read_prop (13)]: vfs_login_url:https://visa.vfsglobal.com/ind/en/deu/login
[2023-05-14 11:12:38,906] DEBUG [_ConfigReader.py root read_prop (13)]: vfs_email:zoe.connick@gmail.com
[2023-05-14 11:12:38,906] DEBUG [_ConfigReader.py root read_prop (13)]: vfs_password:Password1!2
[2023-05-14 11:12:38,906] DEBUG [_VfsClient.py root _login (54)]: Logging in with email: zoe.connick@gmail.com
[2023-05-14 11:12:59,249] DEBUG [_VfsClient.py root _validate_login (77)]: Unable to login. VFS website is not responding
[2023-05-14 11:12:59,250] INFO [vfs_appointment_bot.py __main__ <module> (49)]: Unable to login. VFS website is not responding. Please check the logs for more details
[2023-05-14 11:12:59,251] DEBUG [vfs_appointment_bot.py __main__ <module> (50)]: Unable to login. VFS website is not responding
Traceback (most recent call last):
  File "/Users/kennethyellow/Documents/yellow/vfs-appointment-bot/vfs_appointment_bot/_VfsClient.py", line 70, in _validate_login
    _new_booking_button = self._web_driver.find_element_by_xpath("//section/div/div[2]/button/span")
  File "/Users/kennethyellow/Documents/yellow/vfs-appointment-bot/venv/lib/python3.9/site-packages/selenium/webdriver/remote/webdriver.py", line 394, in find_element_by_xpath
    return self.find_element(by=By.XPATH, value=xpath)
  File "/Users/kennethyellow/Documents/yellow/vfs-appointment-bot/venv/lib/python3.9/site-packages/selenium/webdriver/remote/webdriver.py", line 976, in find_element
    return self.execute(Command.FIND_ELEMENT, {
  File "/Users/kennethyellow/Documents/yellow/vfs-appointment-bot/venv/lib/python3.9/site-packages/selenium/webdriver/remote/webdriver.py", line 321, in execute
    self.error_handler.check_response(response)
  File "/Users/kennethyellow/Documents/yellow/vfs-appointment-bot/venv/lib/python3.9/site-packages/selenium/webdriver/remote/errorhandler.py", line 242, in check_response
    raise exception_class(message, screen, stacktrace)
selenium.common.exceptions.NoSuchElementException: Message: Unable to locate element: //section/div/div[2]/button/span


During handling of the above exception, another exception occurred:

Traceback (most recent call last):
  File "/Users/kennethyellow/Documents/yellow/vfs-appointment-bot/vfs_appointment_bot/vfs_appointment_bot.py", line 45, in <module>
    _vfs_client.check_slot(visa_centre=visa_centre, category=category, sub_category=sub_category)
  File "/Users/kennethyellow/Documents/yellow/vfs-appointment-bot/vfs_appointment_bot/_VfsClient.py", line 151, in check_slot
    self._validate_login()
  File "/Users/kennethyellow/Documents/yellow/vfs-appointment-bot/vfs_appointment_bot/_VfsClient.py", line 78, in _validate_login
    raise Exception("Unable to login. VFS website is not responding")
Exception: Unable to login. VFS website is not responding
Stack (most recent call last):
  File "/Users/kennethyellow/Documents/yellow/vfs-appointment-bot/vfs_appointment_bot/vfs_appointment_bot.py", line 50, in <module>
    logging.debug(e, exc_info=True, stack_info=True)
[2023-05-14 11:15:15,093] DEBUG [_ConfigReader.py root read_prop (13)]: twilio_to_num:to-number
[2023-05-14 11:15:15,093] DEBUG [_ConfigReader.py root read_prop (13)]: twilio_from_num:from-number
[2023-05-14 11:15:15,093] DEBUG [_ConfigReader.py root read_prop (13)]: twilio_account_sid:account-sid
[2023-05-14 11:15:15,093] DEBUG [_ConfigReader.py root read_prop (13)]: twilio_auth_token:auth-token
[2023-05-14 11:15:15,093] DEBUG [_ConfigReader.py root read_prop (13)]: twilio_url:twilio-url
[2023-05-14 11:15:15,093] DEBUG [_ConfigReader.py root read_bool_prop (18)]: twilio_sms_enabled:True
[2023-05-14 11:15:15,093] DEBUG [_ConfigReader.py root read_bool_prop (18)]: twilio_call_enabled:True
[2023-05-14 11:15:15,094] DEBUG [_ConfigReader.py root read_prop (13)]: chat_id:-1001941267897
[2023-05-14 11:15:15,094] DEBUG [_ConfigReader.py root read_prop (13)]: parse_mode:Markdown
[2023-05-14 11:15:15,094] DEBUG [_ConfigReader.py root read_prop (13)]: bot_token:6281742980:AAGIAXJlxLQhzvW4oveGtq9Y7bUxfXyf0Wc
[2023-05-14 11:15:15,094] DEBUG [_ConfigReader.py root read_prop (13)]: use_telegram:True
[2023-05-14 11:15:15,094] DEBUG [_ConfigReader.py root read_prop (13)]: use_twilio:False
[2023-05-14 11:15:15,094] DEBUG [_VfsClient.py root __init__ (25)]: Will use Telegram : True
[2023-05-14 11:15:15,094] DEBUG [_VfsClient.py root __init__ (26)]: Will use Twilio : False
[2023-05-14 11:15:15,094] DEBUG [_ConfigReader.py root read_prop (13)]: interval:120
[2023-05-14 11:15:15,094] DEBUG [vfs_appointment_bot.py __main__ <module> (37)]: Interval: 120
[2023-05-14 11:15:15,094] INFO [vfs_appointment_bot.py __main__ <module> (41)]: Starting VFS Appointment Bot
[2023-05-14 11:15:15,094] INFO [vfs_appointment_bot.py __main__ <module> (44)]: Running VFS Appointment Bot: Attempt#1
[2023-05-14 11:15:17,078] DEBUG [_ConfigReader.py root read_prop (13)]: vfs_login_url:https://visa.vfsglobal.com/gbr/en/prt/application-detail
[2023-05-14 11:15:17,754] DEBUG [_ConfigReader.py root read_prop (13)]: vfs_email:zoe.connick@gmail.com
[2023-05-14 11:15:17,755] DEBUG [_ConfigReader.py root read_prop (13)]: vfs_password:Password1!2
[2023-05-14 11:15:17,755] DEBUG [_VfsClient.py root _login (54)]: Logging in with email: zoe.connick@gmail.com
[2023-05-14 11:15:38,108] DEBUG [_VfsClient.py root _validate_login (77)]: Unable to login. VFS website is not responding
[2023-05-14 11:15:38,108] INFO [vfs_appointment_bot.py __main__ <module> (49)]: Unable to login. VFS website is not responding. Please check the logs for more details
[2023-05-14 11:15:38,109] DEBUG [vfs_appointment_bot.py __main__ <module> (50)]: Unable to login. VFS website is not responding
Traceback (most recent call last):
  File "/Users/kennethyellow/Documents/yellow/vfs-appointment-bot/vfs_appointment_bot/_VfsClient.py", line 70, in _validate_login
    _new_booking_button = self._web_driver.find_element_by_xpath("//section/div/div[2]/button/span")
  File "/Users/kennethyellow/Documents/yellow/vfs-appointment-bot/venv/lib/python3.9/site-packages/selenium/webdriver/remote/webdriver.py", line 394, in find_element_by_xpath
    return self.find_element(by=By.XPATH, value=xpath)
  File "/Users/kennethyellow/Documents/yellow/vfs-appointment-bot/venv/lib/python3.9/site-packages/selenium/webdriver/remote/webdriver.py", line 976, in find_element
    return self.execute(Command.FIND_ELEMENT, {
  File "/Users/kennethyellow/Documents/yellow/vfs-appointment-bot/venv/lib/python3.9/site-packages/selenium/webdriver/remote/webdriver.py", line 321, in execute
    self.error_handler.check_response(response)
  File "/Users/kennethyellow/Documents/yellow/vfs-appointment-bot/venv/lib/python3.9/site-packages/selenium/webdriver/remote/errorhandler.py", line 242, in check_response
    raise exception_class(message, screen, stacktrace)
selenium.common.exceptions.NoSuchElementException: Message: Unable to locate element: //section/div/div[2]/button/span


During handling of the above exception, another exception occurred:

Traceback (most recent call last):
  File "/Users/kennethyellow/Documents/yellow/vfs-appointment-bot/vfs_appointment_bot/vfs_appointment_bot.py", line 45, in <module>
    _vfs_client.check_slot(visa_centre=visa_centre, category=category, sub_category=sub_category)
  File "/Users/kennethyellow/Documents/yellow/vfs-appointment-bot/vfs_appointment_bot/_VfsClient.py", line 151, in check_slot
    self._validate_login()
  File "/Users/kennethyellow/Documents/yellow/vfs-appointment-bot/vfs_appointment_bot/_VfsClient.py", line 78, in _validate_login
    raise Exception("Unable to login. VFS website is not responding")
Exception: Unable to login. VFS website is not responding
Stack (most recent call last):
  File "/Users/kennethyellow/Documents/yellow/vfs-appointment-bot/vfs_appointment_bot/vfs_appointment_bot.py", line 50, in <module>
    logging.debug(e, exc_info=True, stack_info=True)
[2023-05-14 11:24:37,593] DEBUG [_ConfigReader.py root read_prop (13)]: twilio_to_num:to-number
[2023-05-14 11:24:37,593] DEBUG [_ConfigReader.py root read_prop (13)]: twilio_from_num:from-number
[2023-05-14 11:24:37,593] DEBUG [_ConfigReader.py root read_prop (13)]: twilio_account_sid:account-sid
[2023-05-14 11:24:37,593] DEBUG [_ConfigReader.py root read_prop (13)]: twilio_auth_token:auth-token
[2023-05-14 11:24:37,593] DEBUG [_ConfigReader.py root read_prop (13)]: twilio_url:twilio-url
[2023-05-14 11:24:37,593] DEBUG [_ConfigReader.py root read_bool_prop (18)]: twilio_sms_enabled:True
[2023-05-14 11:24:37,593] DEBUG [_ConfigReader.py root read_bool_prop (18)]: twilio_call_enabled:True
[2023-05-14 11:24:37,594] DEBUG [_ConfigReader.py root read_prop (13)]: chat_id:-1001941267897
[2023-05-14 11:24:37,594] DEBUG [_ConfigReader.py root read_prop (13)]: parse_mode:Markdown
[2023-05-14 11:24:37,594] DEBUG [_ConfigReader.py root read_prop (13)]: bot_token:6281742980:AAGIAXJlxLQhzvW4oveGtq9Y7bUxfXyf0Wc
[2023-05-14 11:24:37,594] DEBUG [_ConfigReader.py root read_prop (13)]: use_telegram:True
[2023-05-14 11:24:37,594] DEBUG [_ConfigReader.py root read_prop (13)]: use_twilio:False
[2023-05-14 11:24:37,594] DEBUG [_VfsClient.py root __init__ (25)]: Will use Telegram : True
[2023-05-14 11:24:37,594] DEBUG [_VfsClient.py root __init__ (26)]: Will use Twilio : False
[2023-05-14 11:24:37,594] DEBUG [_ConfigReader.py root read_prop (13)]: interval:120
[2023-05-14 11:24:37,594] DEBUG [vfs_appointment_bot.py __main__ <module> (37)]: Interval: 120
[2023-05-14 11:24:37,594] INFO [vfs_appointment_bot.py __main__ <module> (41)]: Starting VFS Appointment Bot
[2023-05-14 11:24:37,594] INFO [vfs_appointment_bot.py __main__ <module> (44)]: Running VFS Appointment Bot: Attempt#1
[2023-05-14 11:24:39,520] DEBUG [_ConfigReader.py root read_prop (13)]: vfs_login_url:https://visa.vfsglobal.com/gbr/en/prt/login
[2023-05-14 11:24:40,246] DEBUG [_ConfigReader.py root read_prop (13)]: vfs_email:zoe.connick@gmail.com
[2023-05-14 11:24:40,246] DEBUG [_ConfigReader.py root read_prop (13)]: vfs_password:Password1!2
[2023-05-14 11:24:40,246] DEBUG [_VfsClient.py root _login (54)]: Logging in with email: zoe.connick@gmail.com
[2023-05-14 11:25:00,587] DEBUG [_VfsClient.py root _validate_login (75)]: Logged in successfully
[2023-05-14 11:25:00,587] INFO [_VfsClient.py root _get_appointment_date (81)]: Getting appointment date: Visa Centre: Portugal Visa application Centre London, Category: Long Stay, Sub-Category: National Visa
[2023-05-14 11:25:00,592] INFO [vfs_appointment_bot.py __main__ <module> (49)]: Unable to locate element: //section/div/div[2]/button/span. Please check the logs for more details
[2023-05-14 11:25:00,593] DEBUG [vfs_appointment_bot.py __main__ <module> (50)]: Message: Unable to locate element: //section/div/div[2]/button/span
Traceback (most recent call last):
  File "/Users/kennethyellow/Documents/yellow/vfs-appointment-bot/vfs_appointment_bot/vfs_appointment_bot.py", line 45, in <module>
    _vfs_client.check_slot(visa_centre=visa_centre, category=category, sub_category=sub_category)
  File "/Users/kennethyellow/Documents/yellow/vfs-appointment-bot/vfs_appointment_bot/_VfsClient.py", line 153, in check_slot
    _message = self._get_appointment_date(visa_centre, category, sub_category)
  File "/Users/kennethyellow/Documents/yellow/vfs-appointment-bot/vfs_appointment_bot/_VfsClient.py", line 83, in _get_appointment_date
    _new_booking_button = self._web_driver.find_element_by_xpath(
  File "/Users/kennethyellow/Documents/yellow/vfs-appointment-bot/venv/lib/python3.9/site-packages/selenium/webdriver/remote/webdriver.py", line 394, in find_element_by_xpath
    return self.find_element(by=By.XPATH, value=xpath)
  File "/Users/kennethyellow/Documents/yellow/vfs-appointment-bot/venv/lib/python3.9/site-packages/selenium/webdriver/remote/webdriver.py", line 976, in find_element
    return self.execute(Command.FIND_ELEMENT, {
  File "/Users/kennethyellow/Documents/yellow/vfs-appointment-bot/venv/lib/python3.9/site-packages/selenium/webdriver/remote/webdriver.py", line 321, in execute
    self.error_handler.check_response(response)
  File "/Users/kennethyellow/Documents/yellow/vfs-appointment-bot/venv/lib/python3.9/site-packages/selenium/webdriver/remote/errorhandler.py", line 242, in check_response
    raise exception_class(message, screen, stacktrace)
selenium.common.exceptions.NoSuchElementException: Message: Unable to locate element: //section/div/div[2]/button/span
Stack (most recent call last):
  File "/Users/kennethyellow/Documents/yellow/vfs-appointment-bot/vfs_appointment_bot/vfs_appointment_bot.py", line 50, in <module>
    logging.debug(e, exc_info=True, stack_info=True)
[2023-05-14 11:25:54,842] DEBUG [_ConfigReader.py root read_prop (13)]: twilio_to_num:to-number
[2023-05-14 11:25:54,843] DEBUG [_ConfigReader.py root read_prop (13)]: twilio_from_num:from-number
[2023-05-14 11:25:54,843] DEBUG [_ConfigReader.py root read_prop (13)]: twilio_account_sid:account-sid
[2023-05-14 11:25:54,843] DEBUG [_ConfigReader.py root read_prop (13)]: twilio_auth_token:auth-token
[2023-05-14 11:25:54,843] DEBUG [_ConfigReader.py root read_prop (13)]: twilio_url:twilio-url
[2023-05-14 11:25:54,843] DEBUG [_ConfigReader.py root read_bool_prop (18)]: twilio_sms_enabled:True
[2023-05-14 11:25:54,843] DEBUG [_ConfigReader.py root read_bool_prop (18)]: twilio_call_enabled:True
[2023-05-14 11:25:54,843] DEBUG [_ConfigReader.py root read_prop (13)]: chat_id:-1001941267897
[2023-05-14 11:25:54,843] DEBUG [_ConfigReader.py root read_prop (13)]: parse_mode:Markdown
[2023-05-14 11:25:54,843] DEBUG [_ConfigReader.py root read_prop (13)]: bot_token:6281742980:AAGIAXJlxLQhzvW4oveGtq9Y7bUxfXyf0Wc
[2023-05-14 11:25:54,843] DEBUG [_ConfigReader.py root read_prop (13)]: use_telegram:True
[2023-05-14 11:25:54,843] DEBUG [_ConfigReader.py root read_prop (13)]: use_twilio:False
[2023-05-14 11:25:54,843] DEBUG [_VfsClient.py root __init__ (25)]: Will use Telegram : True
[2023-05-14 11:25:54,843] DEBUG [_VfsClient.py root __init__ (26)]: Will use Twilio : False
[2023-05-14 11:25:54,843] DEBUG [_ConfigReader.py root read_prop (13)]: interval:120
[2023-05-14 11:25:54,843] DEBUG [vfs_appointment_bot.py __main__ <module> (37)]: Interval: 120
[2023-05-14 11:25:54,843] INFO [vfs_appointment_bot.py __main__ <module> (41)]: Starting VFS Appointment Bot
[2023-05-14 11:25:54,843] INFO [vfs_appointment_bot.py __main__ <module> (44)]: Running VFS Appointment Bot: Attempt#1
[2023-05-14 11:25:56,750] DEBUG [_ConfigReader.py root read_prop (13)]: vfs_login_url:https://visa.vfsglobal.com/gbr/en/prt/login
[2023-05-14 11:25:57,457] DEBUG [_ConfigReader.py root read_prop (13)]: vfs_email:zoe.connick@gmail.com
[2023-05-14 11:25:57,457] DEBUG [_ConfigReader.py root read_prop (13)]: vfs_password:Password1!2
[2023-05-14 11:25:57,457] DEBUG [_VfsClient.py root _login (54)]: Logging in with email: zoe.connick@gmail.com
[2023-05-14 11:26:17,805] DEBUG [_VfsClient.py root _validate_login (75)]: Logged in successfully
[2023-05-14 11:26:17,805] INFO [_VfsClient.py root _get_appointment_date (81)]: Getting appointment date: Visa Centre: Portugal Visa application Centre London, Category: Long Stay, Sub-Category: National Visa
[2023-05-14 11:26:17,809] INFO [vfs_appointment_bot.py __main__ <module> (49)]: Unable to locate element: //section/div/div[2]/button/span. Please check the logs for more details
[2023-05-14 11:26:17,811] DEBUG [vfs_appointment_bot.py __main__ <module> (50)]: Message: Unable to locate element: //section/div/div[2]/button/span
Traceback (most recent call last):
  File "/Users/kennethyellow/Documents/yellow/vfs-appointment-bot/vfs_appointment_bot/vfs_appointment_bot.py", line 45, in <module>
    _vfs_client.check_slot(visa_centre=visa_centre, category=category, sub_category=sub_category)
  File "/Users/kennethyellow/Documents/yellow/vfs-appointment-bot/vfs_appointment_bot/_VfsClient.py", line 153, in check_slot
    _message = self._get_appointment_date(visa_centre, category, sub_category)
  File "/Users/kennethyellow/Documents/yellow/vfs-appointment-bot/vfs_appointment_bot/_VfsClient.py", line 83, in _get_appointment_date
    _new_booking_button = self._web_driver.find_element_by_xpath(
  File "/Users/kennethyellow/Documents/yellow/vfs-appointment-bot/venv/lib/python3.9/site-packages/selenium/webdriver/remote/webdriver.py", line 394, in find_element_by_xpath
    return self.find_element(by=By.XPATH, value=xpath)
  File "/Users/kennethyellow/Documents/yellow/vfs-appointment-bot/venv/lib/python3.9/site-packages/selenium/webdriver/remote/webdriver.py", line 976, in find_element
    return self.execute(Command.FIND_ELEMENT, {
  File "/Users/kennethyellow/Documents/yellow/vfs-appointment-bot/venv/lib/python3.9/site-packages/selenium/webdriver/remote/webdriver.py", line 321, in execute
    self.error_handler.check_response(response)
  File "/Users/kennethyellow/Documents/yellow/vfs-appointment-bot/venv/lib/python3.9/site-packages/selenium/webdriver/remote/errorhandler.py", line 242, in check_response
    raise exception_class(message, screen, stacktrace)
selenium.common.exceptions.NoSuchElementException: Message: Unable to locate element: //section/div/div[2]/button/span
Stack (most recent call last):
  File "/Users/kennethyellow/Documents/yellow/vfs-appointment-bot/vfs_appointment_bot/vfs_appointment_bot.py", line 50, in <module>
    logging.debug(e, exc_info=True, stack_info=True)
[2023-05-14 11:27:19,052] INFO [vfs_appointment_bot.py __main__ <module> (44)]: Running VFS Appointment Bot: Attempt#2
[2023-05-14 11:27:20,975] DEBUG [_ConfigReader.py root read_prop (13)]: vfs_login_url:https://visa.vfsglobal.com/gbr/en/prt/login
[2023-05-14 11:27:21,837] DEBUG [_ConfigReader.py root read_prop (13)]: vfs_email:zoe.connick@gmail.com
[2023-05-14 11:27:21,837] DEBUG [_ConfigReader.py root read_prop (13)]: vfs_password:Password1!2
[2023-05-14 11:27:21,837] DEBUG [_VfsClient.py root _login (54)]: Logging in with email: zoe.connick@gmail.com
[2023-05-14 11:27:28,151] DEBUG [_ConfigReader.py root read_prop (13)]: twilio_to_num:to-number
[2023-05-14 11:27:28,151] DEBUG [_ConfigReader.py root read_prop (13)]: twilio_from_num:from-number
[2023-05-14 11:27:28,151] DEBUG [_ConfigReader.py root read_prop (13)]: twilio_account_sid:account-sid
[2023-05-14 11:27:28,151] DEBUG [_ConfigReader.py root read_prop (13)]: twilio_auth_token:auth-token
[2023-05-14 11:27:28,151] DEBUG [_ConfigReader.py root read_prop (13)]: twilio_url:twilio-url
[2023-05-14 11:27:28,151] DEBUG [_ConfigReader.py root read_bool_prop (18)]: twilio_sms_enabled:True
[2023-05-14 11:27:28,151] DEBUG [_ConfigReader.py root read_bool_prop (18)]: twilio_call_enabled:True
[2023-05-14 11:27:28,151] DEBUG [_ConfigReader.py root read_prop (13)]: chat_id:-1001941267897
[2023-05-14 11:27:28,151] DEBUG [_ConfigReader.py root read_prop (13)]: parse_mode:Markdown
[2023-05-14 11:27:28,151] DEBUG [_ConfigReader.py root read_prop (13)]: bot_token:6281742980:AAGIAXJlxLQhzvW4oveGtq9Y7bUxfXyf0Wc
[2023-05-14 11:27:28,151] DEBUG [_ConfigReader.py root read_prop (13)]: use_telegram:True
[2023-05-14 11:27:28,151] DEBUG [_ConfigReader.py root read_prop (13)]: use_twilio:False
[2023-05-14 11:27:28,151] DEBUG [_VfsClient.py root __init__ (25)]: Will use Telegram : True
[2023-05-14 11:27:28,151] DEBUG [_VfsClient.py root __init__ (26)]: Will use Twilio : False
[2023-05-14 11:27:28,151] DEBUG [_ConfigReader.py root read_prop (13)]: interval:120
[2023-05-14 11:27:28,151] DEBUG [vfs_appointment_bot.py __main__ <module> (37)]: Interval: 120
[2023-05-14 11:27:28,152] INFO [vfs_appointment_bot.py __main__ <module> (41)]: Starting VFS Appointment Bot
[2023-05-14 11:27:28,152] INFO [vfs_appointment_bot.py __main__ <module> (44)]: Running VFS Appointment Bot: Attempt#1
[2023-05-14 11:27:30,085] DEBUG [_ConfigReader.py root read_prop (13)]: vfs_login_url:https://visa.vfsglobal.com/gbr/en/prt/login
[2023-05-14 11:27:31,037] DEBUG [_ConfigReader.py root read_prop (13)]: vfs_email:zoe.connick@gmail.com
[2023-05-14 11:27:31,037] DEBUG [_ConfigReader.py root read_prop (13)]: vfs_password:Password1!2
[2023-05-14 11:27:31,037] DEBUG [_VfsClient.py root _login (54)]: Logging in with email: zoe.connick@gmail.com
[2023-05-14 11:27:51,388] DEBUG [_VfsClient.py root _validate_login (75)]: Logged in successfully
[2023-05-14 11:27:51,388] INFO [_VfsClient.py root _get_appointment_date (81)]: Getting appointment date: Visa Centre: Portugal Visa application Centre London, Category: Long Stay, Sub-Category: National Visa
[2023-05-14 11:27:58,886] INFO [vfs_appointment_bot.py __main__ <module> (49)]: Visa centre not found: Portugal Visa application Centre London. Please check the logs for more details
[2023-05-14 11:27:58,887] DEBUG [vfs_appointment_bot.py __main__ <module> (50)]: Visa centre not found: Portugal Visa application Centre London
Traceback (most recent call last):
  File "/Users/kennethyellow/Documents/yellow/vfs-appointment-bot/vfs_appointment_bot/_VfsClient.py", line 95, in _get_appointment_date
    _visa_centre = self._web_driver.find_element_by_xpath(
  File "/Users/kennethyellow/Documents/yellow/vfs-appointment-bot/venv/lib/python3.9/site-packages/selenium/webdriver/remote/webdriver.py", line 394, in find_element_by_xpath
    return self.find_element(by=By.XPATH, value=xpath)
  File "/Users/kennethyellow/Documents/yellow/vfs-appointment-bot/venv/lib/python3.9/site-packages/selenium/webdriver/remote/webdriver.py", line 976, in find_element
    return self.execute(Command.FIND_ELEMENT, {
  File "/Users/kennethyellow/Documents/yellow/vfs-appointment-bot/venv/lib/python3.9/site-packages/selenium/webdriver/remote/webdriver.py", line 321, in execute
    self.error_handler.check_response(response)
  File "/Users/kennethyellow/Documents/yellow/vfs-appointment-bot/venv/lib/python3.9/site-packages/selenium/webdriver/remote/errorhandler.py", line 242, in check_response
    raise exception_class(message, screen, stacktrace)
selenium.common.exceptions.NoSuchElementException: Message: Unable to locate element: //mat-option[starts-with(@id,'mat-option-')]/span[contains(text(), 'Portugal Visa application Centre London')]


During handling of the above exception, another exception occurred:

Traceback (most recent call last):
  File "/Users/kennethyellow/Documents/yellow/vfs-appointment-bot/vfs_appointment_bot/vfs_appointment_bot.py", line 45, in <module>
    _vfs_client.check_slot(visa_centre=visa_centre, category=category, sub_category=sub_category)
  File "/Users/kennethyellow/Documents/yellow/vfs-appointment-bot/vfs_appointment_bot/_VfsClient.py", line 153, in check_slot
    _message = self._get_appointment_date(visa_centre, category, sub_category)
  File "/Users/kennethyellow/Documents/yellow/vfs-appointment-bot/vfs_appointment_bot/_VfsClient.py", line 99, in _get_appointment_date
    raise Exception("Visa centre not found: {}".format(visa_centre))
Exception: Visa centre not found: Portugal Visa application Centre London
Stack (most recent call last):
  File "/Users/kennethyellow/Documents/yellow/vfs-appointment-bot/vfs_appointment_bot/vfs_appointment_bot.py", line 50, in <module>
    logging.debug(e, exc_info=True, stack_info=True)
[2023-05-14 11:29:00,129] INFO [vfs_appointment_bot.py __main__ <module> (44)]: Running VFS Appointment Bot: Attempt#2
[2023-05-14 11:29:02,122] DEBUG [_ConfigReader.py root read_prop (13)]: vfs_login_url:https://visa.vfsglobal.com/gbr/en/prt/login
[2023-05-14 11:29:02,790] DEBUG [_ConfigReader.py root read_prop (13)]: vfs_email:zoe.connick@gmail.com
[2023-05-14 11:29:02,790] DEBUG [_ConfigReader.py root read_prop (13)]: vfs_password:Password1!2
[2023-05-14 11:29:02,790] DEBUG [_VfsClient.py root _login (54)]: Logging in with email: zoe.connick@gmail.com
[2023-05-14 11:29:23,137] DEBUG [_VfsClient.py root _validate_login (75)]: Logged in successfully
[2023-05-14 11:29:23,137] INFO [_VfsClient.py root _get_appointment_date (81)]: Getting appointment date: Visa Centre: Portugal Visa application Centre London, Category: Long Stay, Sub-Category: National Visa
[2023-05-14 11:29:30,623] INFO [vfs_appointment_bot.py __main__ <module> (49)]: Visa centre not found: Portugal Visa application Centre London. Please check the logs for more details
[2023-05-14 11:29:30,624] DEBUG [vfs_appointment_bot.py __main__ <module> (50)]: Visa centre not found: Portugal Visa application Centre London
Traceback (most recent call last):
  File "/Users/kennethyellow/Documents/yellow/vfs-appointment-bot/vfs_appointment_bot/_VfsClient.py", line 95, in _get_appointment_date
    _visa_centre = self._web_driver.find_element_by_xpath(
  File "/Users/kennethyellow/Documents/yellow/vfs-appointment-bot/venv/lib/python3.9/site-packages/selenium/webdriver/remote/webdriver.py", line 394, in find_element_by_xpath
    return self.find_element(by=By.XPATH, value=xpath)
  File "/Users/kennethyellow/Documents/yellow/vfs-appointment-bot/venv/lib/python3.9/site-packages/selenium/webdriver/remote/webdriver.py", line 976, in find_element
    return self.execute(Command.FIND_ELEMENT, {
  File "/Users/kennethyellow/Documents/yellow/vfs-appointment-bot/venv/lib/python3.9/site-packages/selenium/webdriver/remote/webdriver.py", line 321, in execute
    self.error_handler.check_response(response)
  File "/Users/kennethyellow/Documents/yellow/vfs-appointment-bot/venv/lib/python3.9/site-packages/selenium/webdriver/remote/errorhandler.py", line 242, in check_response
    raise exception_class(message, screen, stacktrace)
selenium.common.exceptions.NoSuchElementException: Message: Unable to locate element: //mat-option[starts-with(@id,'mat-option-')]/span[contains(text(), 'Portugal Visa application Centre London')]


During handling of the above exception, another exception occurred:

Traceback (most recent call last):
  File "/Users/kennethyellow/Documents/yellow/vfs-appointment-bot/vfs_appointment_bot/vfs_appointment_bot.py", line 45, in <module>
    _vfs_client.check_slot(visa_centre=visa_centre, category=category, sub_category=sub_category)
  File "/Users/kennethyellow/Documents/yellow/vfs-appointment-bot/vfs_appointment_bot/_VfsClient.py", line 153, in check_slot
    _message = self._get_appointment_date(visa_centre, category, sub_category)
  File "/Users/kennethyellow/Documents/yellow/vfs-appointment-bot/vfs_appointment_bot/_VfsClient.py", line 99, in _get_appointment_date
    raise Exception("Visa centre not found: {}".format(visa_centre))
Exception: Visa centre not found: Portugal Visa application Centre London
Stack (most recent call last):
  File "/Users/kennethyellow/Documents/yellow/vfs-appointment-bot/vfs_appointment_bot/vfs_appointment_bot.py", line 50, in <module>
    logging.debug(e, exc_info=True, stack_info=True)
[2023-05-14 11:30:31,853] INFO [vfs_appointment_bot.py __main__ <module> (44)]: Running VFS Appointment Bot: Attempt#3
[2023-05-14 11:30:33,787] DEBUG [_ConfigReader.py root read_prop (13)]: vfs_login_url:https://visa.vfsglobal.com/gbr/en/prt/login
[2023-05-14 11:30:34,768] DEBUG [_ConfigReader.py root read_prop (13)]: vfs_email:zoe.connick@gmail.com
[2023-05-14 11:30:34,768] DEBUG [_ConfigReader.py root read_prop (13)]: vfs_password:Password1!2
[2023-05-14 11:30:34,768] DEBUG [_VfsClient.py root _login (54)]: Logging in with email: zoe.connick@gmail.com
[2023-05-14 11:30:55,115] DEBUG [_VfsClient.py root _validate_login (75)]: Logged in successfully
[2023-05-14 11:30:55,115] INFO [_VfsClient.py root _get_appointment_date (81)]: Getting appointment date: Visa Centre: Portugal Visa application Centre London, Category: Long Stay, Sub-Category: National Visa
[2023-05-14 11:31:02,609] INFO [vfs_appointment_bot.py __main__ <module> (49)]: Visa centre not found: Portugal Visa application Centre London. Please check the logs for more details
[2023-05-14 11:31:02,610] DEBUG [vfs_appointment_bot.py __main__ <module> (50)]: Visa centre not found: Portugal Visa application Centre London
Traceback (most recent call last):
  File "/Users/kennethyellow/Documents/yellow/vfs-appointment-bot/vfs_appointment_bot/_VfsClient.py", line 95, in _get_appointment_date
    _visa_centre = self._web_driver.find_element_by_xpath(
  File "/Users/kennethyellow/Documents/yellow/vfs-appointment-bot/venv/lib/python3.9/site-packages/selenium/webdriver/remote/webdriver.py", line 394, in find_element_by_xpath
    return self.find_element(by=By.XPATH, value=xpath)
  File "/Users/kennethyellow/Documents/yellow/vfs-appointment-bot/venv/lib/python3.9/site-packages/selenium/webdriver/remote/webdriver.py", line 976, in find_element
    return self.execute(Command.FIND_ELEMENT, {
  File "/Users/kennethyellow/Documents/yellow/vfs-appointment-bot/venv/lib/python3.9/site-packages/selenium/webdriver/remote/webdriver.py", line 321, in execute
    self.error_handler.check_response(response)
  File "/Users/kennethyellow/Documents/yellow/vfs-appointment-bot/venv/lib/python3.9/site-packages/selenium/webdriver/remote/errorhandler.py", line 242, in check_response
    raise exception_class(message, screen, stacktrace)
selenium.common.exceptions.NoSuchElementException: Message: Unable to locate element: //mat-option[starts-with(@id,'mat-option-')]/span[contains(text(), 'Portugal Visa application Centre London')]


During handling of the above exception, another exception occurred:

Traceback (most recent call last):
  File "/Users/kennethyellow/Documents/yellow/vfs-appointment-bot/vfs_appointment_bot/vfs_appointment_bot.py", line 45, in <module>
    _vfs_client.check_slot(visa_centre=visa_centre, category=category, sub_category=sub_category)
  File "/Users/kennethyellow/Documents/yellow/vfs-appointment-bot/vfs_appointment_bot/_VfsClient.py", line 153, in check_slot
    _message = self._get_appointment_date(visa_centre, category, sub_category)
  File "/Users/kennethyellow/Documents/yellow/vfs-appointment-bot/vfs_appointment_bot/_VfsClient.py", line 99, in _get_appointment_date
    raise Exception("Visa centre not found: {}".format(visa_centre))
Exception: Visa centre not found: Portugal Visa application Centre London
Stack (most recent call last):
  File "/Users/kennethyellow/Documents/yellow/vfs-appointment-bot/vfs_appointment_bot/vfs_appointment_bot.py", line 50, in <module>
    logging.debug(e, exc_info=True, stack_info=True)
[2023-05-14 11:36:30,342] DEBUG [_ConfigReader.py root read_prop (13)]: twilio_to_num:to-number
[2023-05-14 11:36:30,342] DEBUG [_ConfigReader.py root read_prop (13)]: twilio_from_num:from-number
[2023-05-14 11:36:30,343] DEBUG [_ConfigReader.py root read_prop (13)]: twilio_account_sid:account-sid
[2023-05-14 11:36:30,343] DEBUG [_ConfigReader.py root read_prop (13)]: twilio_auth_token:auth-token
[2023-05-14 11:36:30,343] DEBUG [_ConfigReader.py root read_prop (13)]: twilio_url:twilio-url
[2023-05-14 11:36:30,343] DEBUG [_ConfigReader.py root read_bool_prop (18)]: twilio_sms_enabled:True
[2023-05-14 11:36:30,343] DEBUG [_ConfigReader.py root read_bool_prop (18)]: twilio_call_enabled:True
[2023-05-14 11:36:30,343] DEBUG [_ConfigReader.py root read_prop (13)]: chat_id:-1001941267897
[2023-05-14 11:36:30,343] DEBUG [_ConfigReader.py root read_prop (13)]: parse_mode:Markdown
[2023-05-14 11:36:30,343] DEBUG [_ConfigReader.py root read_prop (13)]: bot_token:6281742980:AAGIAXJlxLQhzvW4oveGtq9Y7bUxfXyf0Wc
[2023-05-14 11:36:30,343] DEBUG [_ConfigReader.py root read_prop (13)]: use_telegram:True
[2023-05-14 11:36:30,343] DEBUG [_ConfigReader.py root read_prop (13)]: use_twilio:False
[2023-05-14 11:36:30,343] DEBUG [_VfsClient.py root __init__ (25)]: Will use Telegram : True
[2023-05-14 11:36:30,343] DEBUG [_VfsClient.py root __init__ (26)]: Will use Twilio : False
[2023-05-14 11:36:30,343] DEBUG [_ConfigReader.py root read_prop (13)]: interval:120
[2023-05-14 11:36:30,343] DEBUG [vfs_appointment_bot.py __main__ <module> (37)]: Interval: 120
[2023-05-14 11:36:30,343] INFO [vfs_appointment_bot.py __main__ <module> (41)]: Starting VFS Appointment Bot
[2023-05-14 11:36:30,343] INFO [vfs_appointment_bot.py __main__ <module> (44)]: Running VFS Appointment Bot: Attempt#1
[2023-05-14 11:36:32,259] DEBUG [_ConfigReader.py root read_prop (13)]: vfs_login_url:https://visa.vfsglobal.com/gbr/en/prt/login
[2023-05-14 11:36:32,963] DEBUG [_ConfigReader.py root read_prop (13)]: vfs_email:zoe.connick@gmail.com
[2023-05-14 11:36:32,963] DEBUG [_ConfigReader.py root read_prop (13)]: vfs_password:Password1!2
[2023-05-14 11:36:32,963] DEBUG [_VfsClient.py root _login (54)]: Logging in with email: zoe.connick@gmail.com
[2023-05-14 11:36:53,308] DEBUG [_VfsClient.py root _validate_login (75)]: Logged in successfully
[2023-05-14 11:36:53,309] INFO [_VfsClient.py root _get_appointment_date (81)]: Getting appointment date: Visa Centre:  Portugal Visa application Centre London , Category: Long Stay, Sub-Category: National Visa
[2023-05-14 11:37:00,801] INFO [vfs_appointment_bot.py __main__ <module> (49)]: Visa centre not found:  Portugal Visa application Centre London . Please check the logs for more details
[2023-05-14 11:37:00,803] DEBUG [vfs_appointment_bot.py __main__ <module> (50)]: Visa centre not found:  Portugal Visa application Centre London 
Traceback (most recent call last):
  File "/Users/kennethyellow/Documents/yellow/vfs-appointment-bot/vfs_appointment_bot/_VfsClient.py", line 95, in _get_appointment_date
    _visa_centre = self._web_driver.find_element_by_xpath(
  File "/Users/kennethyellow/Documents/yellow/vfs-appointment-bot/venv/lib/python3.9/site-packages/selenium/webdriver/remote/webdriver.py", line 394, in find_element_by_xpath
    return self.find_element(by=By.XPATH, value=xpath)
  File "/Users/kennethyellow/Documents/yellow/vfs-appointment-bot/venv/lib/python3.9/site-packages/selenium/webdriver/remote/webdriver.py", line 976, in find_element
    return self.execute(Command.FIND_ELEMENT, {
  File "/Users/kennethyellow/Documents/yellow/vfs-appointment-bot/venv/lib/python3.9/site-packages/selenium/webdriver/remote/webdriver.py", line 321, in execute
    self.error_handler.check_response(response)
  File "/Users/kennethyellow/Documents/yellow/vfs-appointment-bot/venv/lib/python3.9/site-packages/selenium/webdriver/remote/errorhandler.py", line 242, in check_response
    raise exception_class(message, screen, stacktrace)
selenium.common.exceptions.NoSuchElementException: Message: Unable to locate element: //mat-option[starts-with(@id,'mat-option-')]/span[contains(text(), ' Portugal Visa application Centre London ')]


During handling of the above exception, another exception occurred:

Traceback (most recent call last):
  File "/Users/kennethyellow/Documents/yellow/vfs-appointment-bot/vfs_appointment_bot/vfs_appointment_bot.py", line 45, in <module>
    _vfs_client.check_slot(visa_centre=visa_centre, category=category, sub_category=sub_category)
  File "/Users/kennethyellow/Documents/yellow/vfs-appointment-bot/vfs_appointment_bot/_VfsClient.py", line 153, in check_slot
    _message = self._get_appointment_date(visa_centre, category, sub_category)
  File "/Users/kennethyellow/Documents/yellow/vfs-appointment-bot/vfs_appointment_bot/_VfsClient.py", line 99, in _get_appointment_date
    raise Exception("Visa centre not found: {}".format(visa_centre))
Exception: Visa centre not found:  Portugal Visa application Centre London 
Stack (most recent call last):
  File "/Users/kennethyellow/Documents/yellow/vfs-appointment-bot/vfs_appointment_bot/vfs_appointment_bot.py", line 50, in <module>
    logging.debug(e, exc_info=True, stack_info=True)
[2023-05-14 11:37:13,608] DEBUG [_ConfigReader.py root read_prop (13)]: twilio_to_num:to-number
[2023-05-14 11:37:13,608] DEBUG [_ConfigReader.py root read_prop (13)]: twilio_from_num:from-number
[2023-05-14 11:37:13,608] DEBUG [_ConfigReader.py root read_prop (13)]: twilio_account_sid:account-sid
[2023-05-14 11:37:13,608] DEBUG [_ConfigReader.py root read_prop (13)]: twilio_auth_token:auth-token
[2023-05-14 11:37:13,608] DEBUG [_ConfigReader.py root read_prop (13)]: twilio_url:twilio-url
[2023-05-14 11:37:13,608] DEBUG [_ConfigReader.py root read_bool_prop (18)]: twilio_sms_enabled:True
[2023-05-14 11:37:13,608] DEBUG [_ConfigReader.py root read_bool_prop (18)]: twilio_call_enabled:True
[2023-05-14 11:37:13,608] DEBUG [_ConfigReader.py root read_prop (13)]: chat_id:-1001941267897
[2023-05-14 11:37:13,608] DEBUG [_ConfigReader.py root read_prop (13)]: parse_mode:Markdown
[2023-05-14 11:37:13,608] DEBUG [_ConfigReader.py root read_prop (13)]: bot_token:6281742980:AAGIAXJlxLQhzvW4oveGtq9Y7bUxfXyf0Wc
[2023-05-14 11:37:13,608] DEBUG [_ConfigReader.py root read_prop (13)]: use_telegram:True
[2023-05-14 11:37:13,608] DEBUG [_ConfigReader.py root read_prop (13)]: use_twilio:False
[2023-05-14 11:37:13,608] DEBUG [_VfsClient.py root __init__ (25)]: Will use Telegram : True
[2023-05-14 11:37:13,608] DEBUG [_VfsClient.py root __init__ (26)]: Will use Twilio : False
[2023-05-14 11:37:13,608] DEBUG [_ConfigReader.py root read_prop (13)]: interval:120
[2023-05-14 11:37:13,608] DEBUG [vfs_appointment_bot.py __main__ <module> (37)]: Interval: 120
[2023-05-14 11:37:13,608] INFO [vfs_appointment_bot.py __main__ <module> (41)]: Starting VFS Appointment Bot
[2023-05-14 11:37:13,608] INFO [vfs_appointment_bot.py __main__ <module> (44)]: Running VFS Appointment Bot: Attempt#1
[2023-05-14 11:37:15,549] DEBUG [_ConfigReader.py root read_prop (13)]: vfs_login_url:https://visa.vfsglobal.com/gbr/en/prt/login
[2023-05-14 11:37:16,249] DEBUG [_ConfigReader.py root read_prop (13)]: vfs_email:zoe.connick@gmail.com
[2023-05-14 11:37:16,249] DEBUG [_ConfigReader.py root read_prop (13)]: vfs_password:Password1!2
[2023-05-14 11:37:16,249] DEBUG [_VfsClient.py root _login (54)]: Logging in with email: zoe.connick@gmail.com
[2023-05-14 11:37:36,597] DEBUG [_VfsClient.py root _validate_login (75)]: Logged in successfully
[2023-05-14 11:37:36,597] INFO [_VfsClient.py root _get_appointment_date (81)]: Getting appointment date: Visa Centre:  Portugal Visa application Centre London , Category: Long Stay, Sub-Category: National Visa
[2023-05-14 11:37:44,095] INFO [vfs_appointment_bot.py __main__ <module> (49)]: Visa centre not found:  Portugal Visa application Centre London . Please check the logs for more details
[2023-05-14 11:37:44,097] DEBUG [vfs_appointment_bot.py __main__ <module> (50)]: Visa centre not found:  Portugal Visa application Centre London 
Traceback (most recent call last):
  File "/Users/kennethyellow/Documents/yellow/vfs-appointment-bot/vfs_appointment_bot/_VfsClient.py", line 95, in _get_appointment_date
    _visa_centre = self._web_driver.find_element_by_xpath(
  File "/Users/kennethyellow/Documents/yellow/vfs-appointment-bot/venv/lib/python3.9/site-packages/selenium/webdriver/remote/webdriver.py", line 394, in find_element_by_xpath
    return self.find_element(by=By.XPATH, value=xpath)
  File "/Users/kennethyellow/Documents/yellow/vfs-appointment-bot/venv/lib/python3.9/site-packages/selenium/webdriver/remote/webdriver.py", line 976, in find_element
    return self.execute(Command.FIND_ELEMENT, {
  File "/Users/kennethyellow/Documents/yellow/vfs-appointment-bot/venv/lib/python3.9/site-packages/selenium/webdriver/remote/webdriver.py", line 321, in execute
    self.error_handler.check_response(response)
  File "/Users/kennethyellow/Documents/yellow/vfs-appointment-bot/venv/lib/python3.9/site-packages/selenium/webdriver/remote/errorhandler.py", line 242, in check_response
    raise exception_class(message, screen, stacktrace)
selenium.common.exceptions.NoSuchElementException: Message: Unable to locate element: //mat-option[starts-with(@id,'mat-option-')]/span[contains(text(), ' Portugal Visa application Centre London ')]


During handling of the above exception, another exception occurred:

Traceback (most recent call last):
  File "/Users/kennethyellow/Documents/yellow/vfs-appointment-bot/vfs_appointment_bot/vfs_appointment_bot.py", line 45, in <module>
    _vfs_client.check_slot(visa_centre=visa_centre, category=category, sub_category=sub_category)
  File "/Users/kennethyellow/Documents/yellow/vfs-appointment-bot/vfs_appointment_bot/_VfsClient.py", line 153, in check_slot
    _message = self._get_appointment_date(visa_centre, category, sub_category)
  File "/Users/kennethyellow/Documents/yellow/vfs-appointment-bot/vfs_appointment_bot/_VfsClient.py", line 99, in _get_appointment_date
    raise Exception("Visa centre not found: {}".format(visa_centre))
Exception: Visa centre not found:  Portugal Visa application Centre London 
Stack (most recent call last):
  File "/Users/kennethyellow/Documents/yellow/vfs-appointment-bot/vfs_appointment_bot/vfs_appointment_bot.py", line 50, in <module>
    logging.debug(e, exc_info=True, stack_info=True)
[2023-05-14 12:18:00,547] DEBUG [_ConfigReader.py root read_prop (13)]: twilio_to_num:to-number
[2023-05-14 12:18:00,547] DEBUG [_ConfigReader.py root read_prop (13)]: twilio_from_num:from-number
[2023-05-14 12:18:00,547] DEBUG [_ConfigReader.py root read_prop (13)]: twilio_account_sid:account-sid
[2023-05-14 12:18:00,547] DEBUG [_ConfigReader.py root read_prop (13)]: twilio_auth_token:auth-token
[2023-05-14 12:18:00,547] DEBUG [_ConfigReader.py root read_prop (13)]: twilio_url:twilio-url
[2023-05-14 12:18:00,547] DEBUG [_ConfigReader.py root read_bool_prop (18)]: twilio_sms_enabled:True
[2023-05-14 12:18:00,547] DEBUG [_ConfigReader.py root read_bool_prop (18)]: twilio_call_enabled:True
[2023-05-14 12:18:00,547] DEBUG [_ConfigReader.py root read_prop (13)]: chat_id:-1001941267897
[2023-05-14 12:18:00,547] DEBUG [_ConfigReader.py root read_prop (13)]: parse_mode:Markdown
[2023-05-14 12:18:00,547] DEBUG [_ConfigReader.py root read_prop (13)]: bot_token:6281742980:AAGIAXJlxLQhzvW4oveGtq9Y7bUxfXyf0Wc
[2023-05-14 12:18:00,547] DEBUG [_ConfigReader.py root read_prop (13)]: use_telegram:True
[2023-05-14 12:18:00,547] DEBUG [_ConfigReader.py root read_prop (13)]: use_twilio:False
[2023-05-14 12:18:00,547] DEBUG [_VfsClient.py root __init__ (25)]: Will use Telegram : True
[2023-05-14 12:18:00,547] DEBUG [_VfsClient.py root __init__ (26)]: Will use Twilio : False
[2023-05-14 12:18:00,548] DEBUG [_ConfigReader.py root read_prop (13)]: interval:120
[2023-05-14 12:18:00,548] DEBUG [vfs_appointment_bot.py __main__ <module> (37)]: Interval: 120
[2023-05-14 12:18:00,548] INFO [vfs_appointment_bot.py __main__ <module> (41)]: Starting VFS Appointment Bot
[2023-05-14 12:18:00,548] INFO [vfs_appointment_bot.py __main__ <module> (44)]: Running VFS Appointment Bot: Attempt#1
[2023-05-14 12:18:02,478] DEBUG [_ConfigReader.py root read_prop (13)]: vfs_login_url:https://visa.vfsglobal.com/gbr/en/prt/login
[2023-05-14 12:18:03,271] DEBUG [_ConfigReader.py root read_prop (13)]: vfs_email:zoe.connick@gmail.com
[2023-05-14 12:18:03,271] DEBUG [_ConfigReader.py root read_prop (13)]: vfs_password:Password1!2
[2023-05-14 12:18:03,271] DEBUG [_VfsClient.py root _login (54)]: Logging in with email: zoe.connick@gmail.com
[2023-05-14 12:18:23,614] DEBUG [_VfsClient.py root _validate_login (75)]: Logged in successfully
[2023-05-14 12:18:23,615] INFO [_VfsClient.py root _get_appointment_date (81)]: Getting appointment date: Visa Centre: Portugal Visa application Centre London, Category: Long Stay, Sub-Category: National Visa
[2023-05-14 12:18:23,624] INFO [vfs_appointment_bot.py __main__ <module> (49)]: Unable to locate element: //html/body/app-root/div/app-dashboard/section[1]/div/div[2]/button. Please check the logs for more details
[2023-05-14 12:18:23,626] DEBUG [vfs_appointment_bot.py __main__ <module> (50)]: Message: Unable to locate element: //html/body/app-root/div/app-dashboard/section[1]/div/div[2]/button
Traceback (most recent call last):
  File "/Users/kennethyellow/Documents/yellow/vfs-appointment-bot/vfs_appointment_bot/vfs_appointment_bot.py", line 45, in <module>
    _vfs_client.check_slot(visa_centre=visa_centre, category=category, sub_category=sub_category)
  File "/Users/kennethyellow/Documents/yellow/vfs-appointment-bot/vfs_appointment_bot/_VfsClient.py", line 153, in check_slot
    _message = self._get_appointment_date(visa_centre, category, sub_category)
  File "/Users/kennethyellow/Documents/yellow/vfs-appointment-bot/vfs_appointment_bot/_VfsClient.py", line 83, in _get_appointment_date
    _new_booking_button = self._web_driver.find_element_by_xpath(
  File "/Users/kennethyellow/Documents/yellow/vfs-appointment-bot/venv/lib/python3.9/site-packages/selenium/webdriver/remote/webdriver.py", line 394, in find_element_by_xpath
    return self.find_element(by=By.XPATH, value=xpath)
  File "/Users/kennethyellow/Documents/yellow/vfs-appointment-bot/venv/lib/python3.9/site-packages/selenium/webdriver/remote/webdriver.py", line 976, in find_element
    return self.execute(Command.FIND_ELEMENT, {
  File "/Users/kennethyellow/Documents/yellow/vfs-appointment-bot/venv/lib/python3.9/site-packages/selenium/webdriver/remote/webdriver.py", line 321, in execute
    self.error_handler.check_response(response)
  File "/Users/kennethyellow/Documents/yellow/vfs-appointment-bot/venv/lib/python3.9/site-packages/selenium/webdriver/remote/errorhandler.py", line 242, in check_response
    raise exception_class(message, screen, stacktrace)
selenium.common.exceptions.NoSuchElementException: Message: Unable to locate element: //html/body/app-root/div/app-dashboard/section[1]/div/div[2]/button
Stack (most recent call last):
  File "/Users/kennethyellow/Documents/yellow/vfs-appointment-bot/vfs_appointment_bot/vfs_appointment_bot.py", line 50, in <module>
    logging.debug(e, exc_info=True, stack_info=True)
[2023-05-14 12:20:39,616] DEBUG [_ConfigReader.py root read_prop (13)]: twilio_to_num:to-number
[2023-05-14 12:20:39,616] DEBUG [_ConfigReader.py root read_prop (13)]: twilio_from_num:from-number
[2023-05-14 12:20:39,616] DEBUG [_ConfigReader.py root read_prop (13)]: twilio_account_sid:account-sid
[2023-05-14 12:20:39,616] DEBUG [_ConfigReader.py root read_prop (13)]: twilio_auth_token:auth-token
[2023-05-14 12:20:39,616] DEBUG [_ConfigReader.py root read_prop (13)]: twilio_url:twilio-url
[2023-05-14 12:20:39,616] DEBUG [_ConfigReader.py root read_bool_prop (18)]: twilio_sms_enabled:True
[2023-05-14 12:20:39,616] DEBUG [_ConfigReader.py root read_bool_prop (18)]: twilio_call_enabled:True
[2023-05-14 12:20:39,616] DEBUG [_ConfigReader.py root read_prop (13)]: chat_id:-1001941267897
[2023-05-14 12:20:39,616] DEBUG [_ConfigReader.py root read_prop (13)]: parse_mode:Markdown
[2023-05-14 12:20:39,616] DEBUG [_ConfigReader.py root read_prop (13)]: bot_token:6281742980:AAGIAXJlxLQhzvW4oveGtq9Y7bUxfXyf0Wc
[2023-05-14 12:20:39,616] DEBUG [_ConfigReader.py root read_prop (13)]: use_telegram:True
[2023-05-14 12:20:39,616] DEBUG [_ConfigReader.py root read_prop (13)]: use_twilio:False
[2023-05-14 12:20:39,616] DEBUG [_VfsClient.py root __init__ (25)]: Will use Telegram : True
[2023-05-14 12:20:39,616] DEBUG [_VfsClient.py root __init__ (26)]: Will use Twilio : False
[2023-05-14 12:20:39,617] DEBUG [_ConfigReader.py root read_prop (13)]: interval:120
[2023-05-14 12:20:39,617] DEBUG [vfs_appointment_bot.py __main__ <module> (37)]: Interval: 120
[2023-05-14 12:20:39,617] INFO [vfs_appointment_bot.py __main__ <module> (41)]: Starting VFS Appointment Bot
[2023-05-14 12:20:39,617] INFO [vfs_appointment_bot.py __main__ <module> (44)]: Running VFS Appointment Bot: Attempt#1
[2023-05-14 12:20:41,559] DEBUG [_ConfigReader.py root read_prop (13)]: vfs_login_url:https://visa.vfsglobal.com/gbr/en/prt/login
[2023-05-14 12:20:42,250] DEBUG [_ConfigReader.py root read_prop (13)]: vfs_email:zoe.connick@gmail.com
[2023-05-14 12:20:42,250] DEBUG [_ConfigReader.py root read_prop (13)]: vfs_password:Password1!2
[2023-05-14 12:20:42,250] DEBUG [_VfsClient.py root _login (54)]: Logging in with email: zoe.connick@gmail.com
[2023-05-14 12:21:02,595] DEBUG [_VfsClient.py root _validate_login (75)]: Logged in successfully
[2023-05-14 12:21:02,595] INFO [_VfsClient.py root _get_appointment_date (81)]: Getting appointment date: Visa Centre: Portugal Visa application Centre London, Category: Long Stay, Sub-Category: National Visa
[2023-05-14 12:21:02,599] INFO [vfs_appointment_bot.py __main__ <module> (49)]: Unable to locate element: //section/div/div[2]/button/span. Please check the logs for more details
[2023-05-14 12:21:02,601] DEBUG [vfs_appointment_bot.py __main__ <module> (50)]: Message: Unable to locate element: //section/div/div[2]/button/span
Traceback (most recent call last):
  File "/Users/kennethyellow/Documents/yellow/vfs-appointment-bot/vfs_appointment_bot/vfs_appointment_bot.py", line 45, in <module>
    _vfs_client.check_slot(visa_centre=visa_centre, category=category, sub_category=sub_category)
  File "/Users/kennethyellow/Documents/yellow/vfs-appointment-bot/vfs_appointment_bot/_VfsClient.py", line 157, in check_slot
    _message = self._get_appointment_date(visa_centre, category, sub_category)
  File "/Users/kennethyellow/Documents/yellow/vfs-appointment-bot/vfs_appointment_bot/_VfsClient.py", line 83, in _get_appointment_date
    _new_booking_button = self._web_driver.find_element_by_xpath(
  File "/Users/kennethyellow/Documents/yellow/vfs-appointment-bot/venv/lib/python3.9/site-packages/selenium/webdriver/remote/webdriver.py", line 394, in find_element_by_xpath
    return self.find_element(by=By.XPATH, value=xpath)
  File "/Users/kennethyellow/Documents/yellow/vfs-appointment-bot/venv/lib/python3.9/site-packages/selenium/webdriver/remote/webdriver.py", line 976, in find_element
    return self.execute(Command.FIND_ELEMENT, {
  File "/Users/kennethyellow/Documents/yellow/vfs-appointment-bot/venv/lib/python3.9/site-packages/selenium/webdriver/remote/webdriver.py", line 321, in execute
    self.error_handler.check_response(response)
  File "/Users/kennethyellow/Documents/yellow/vfs-appointment-bot/venv/lib/python3.9/site-packages/selenium/webdriver/remote/errorhandler.py", line 242, in check_response
    raise exception_class(message, screen, stacktrace)
selenium.common.exceptions.NoSuchElementException: Message: Unable to locate element: //section/div/div[2]/button/span
Stack (most recent call last):
  File "/Users/kennethyellow/Documents/yellow/vfs-appointment-bot/vfs_appointment_bot/vfs_appointment_bot.py", line 50, in <module>
    logging.debug(e, exc_info=True, stack_info=True)
[2023-05-14 12:23:55,994] DEBUG [_ConfigReader.py root read_prop (13)]: twilio_to_num:to-number
[2023-05-14 12:23:55,994] DEBUG [_ConfigReader.py root read_prop (13)]: twilio_from_num:from-number
[2023-05-14 12:23:55,994] DEBUG [_ConfigReader.py root read_prop (13)]: twilio_account_sid:account-sid
[2023-05-14 12:23:55,994] DEBUG [_ConfigReader.py root read_prop (13)]: twilio_auth_token:auth-token
[2023-05-14 12:23:55,994] DEBUG [_ConfigReader.py root read_prop (13)]: twilio_url:twilio-url
[2023-05-14 12:23:55,994] DEBUG [_ConfigReader.py root read_bool_prop (18)]: twilio_sms_enabled:True
[2023-05-14 12:23:55,994] DEBUG [_ConfigReader.py root read_bool_prop (18)]: twilio_call_enabled:True
[2023-05-14 12:23:55,994] DEBUG [_ConfigReader.py root read_prop (13)]: chat_id:-1001941267897
[2023-05-14 12:23:55,994] DEBUG [_ConfigReader.py root read_prop (13)]: parse_mode:Markdown
[2023-05-14 12:23:55,994] DEBUG [_ConfigReader.py root read_prop (13)]: bot_token:6281742980:AAGIAXJlxLQhzvW4oveGtq9Y7bUxfXyf0Wc
[2023-05-14 12:23:55,994] DEBUG [_ConfigReader.py root read_prop (13)]: use_telegram:True
[2023-05-14 12:23:55,994] DEBUG [_ConfigReader.py root read_prop (13)]: use_twilio:False
[2023-05-14 12:23:55,994] DEBUG [_VfsClient.py root __init__ (25)]: Will use Telegram : True
[2023-05-14 12:23:55,994] DEBUG [_VfsClient.py root __init__ (26)]: Will use Twilio : False
[2023-05-14 12:23:55,994] DEBUG [_ConfigReader.py root read_prop (13)]: interval:120
[2023-05-14 12:23:55,994] DEBUG [vfs_appointment_bot.py __main__ <module> (37)]: Interval: 120
[2023-05-14 12:23:55,994] INFO [vfs_appointment_bot.py __main__ <module> (41)]: Starting VFS Appointment Bot
[2023-05-14 12:23:55,994] INFO [vfs_appointment_bot.py __main__ <module> (44)]: Running VFS Appointment Bot: Attempt#1
[2023-05-14 12:23:57,938] DEBUG [_ConfigReader.py root read_prop (13)]: vfs_login_url:https://visa.vfsglobal.com/gbr/en/prt/login
[2023-05-14 12:23:58,755] DEBUG [_ConfigReader.py root read_prop (13)]: vfs_email:zoe.connick@gmail.com
[2023-05-14 12:23:58,755] DEBUG [_ConfigReader.py root read_prop (13)]: vfs_password:Password1!2
[2023-05-14 12:23:58,755] DEBUG [_VfsClient.py root _login (54)]: Logging in with email: zoe.connick@gmail.com
[2023-05-14 12:24:19,102] DEBUG [_VfsClient.py root _validate_login (75)]: Logged in successfully
[2023-05-14 12:24:19,103] INFO [_VfsClient.py root _get_appointment_date (81)]: Getting appointment date: Visa Centre: Portugal Visa application Centre London, Category: Long Stay, Sub-Category: National Visa
[2023-05-14 12:24:26,590] INFO [vfs_appointment_bot.py __main__ <module> (49)]: Visa centre not found: Portugal Visa application Centre London. Please check the logs for more details
[2023-05-14 12:24:26,592] DEBUG [vfs_appointment_bot.py __main__ <module> (50)]: Visa centre not found: Portugal Visa application Centre London
Traceback (most recent call last):
  File "/Users/kennethyellow/Documents/yellow/vfs-appointment-bot/vfs_appointment_bot/_VfsClient.py", line 99, in _get_appointment_date
    _visa_centre = self._web_driver.find_element_by_xpath(
  File "/Users/kennethyellow/Documents/yellow/vfs-appointment-bot/venv/lib/python3.9/site-packages/selenium/webdriver/remote/webdriver.py", line 394, in find_element_by_xpath
    return self.find_element(by=By.XPATH, value=xpath)
  File "/Users/kennethyellow/Documents/yellow/vfs-appointment-bot/venv/lib/python3.9/site-packages/selenium/webdriver/remote/webdriver.py", line 976, in find_element
    return self.execute(Command.FIND_ELEMENT, {
  File "/Users/kennethyellow/Documents/yellow/vfs-appointment-bot/venv/lib/python3.9/site-packages/selenium/webdriver/remote/webdriver.py", line 321, in execute
    self.error_handler.check_response(response)
  File "/Users/kennethyellow/Documents/yellow/vfs-appointment-bot/venv/lib/python3.9/site-packages/selenium/webdriver/remote/errorhandler.py", line 242, in check_response
    raise exception_class(message, screen, stacktrace)
selenium.common.exceptions.NoSuchElementException: Message: Unable to locate element: //mat-option[starts-with(@id,'mat-option-')]/span[contains(text(), 'Portugal Visa application Centre London')]


During handling of the above exception, another exception occurred:

Traceback (most recent call last):
  File "/Users/kennethyellow/Documents/yellow/vfs-appointment-bot/vfs_appointment_bot/vfs_appointment_bot.py", line 45, in <module>
    _vfs_client.check_slot(visa_centre=visa_centre, category=category, sub_category=sub_category)
  File "/Users/kennethyellow/Documents/yellow/vfs-appointment-bot/vfs_appointment_bot/_VfsClient.py", line 157, in check_slot
    _message = self._get_appointment_date(visa_centre, category, sub_category)
  File "/Users/kennethyellow/Documents/yellow/vfs-appointment-bot/vfs_appointment_bot/_VfsClient.py", line 103, in _get_appointment_date
    raise Exception("Visa centre not found: {}".format(visa_centre))
Exception: Visa centre not found: Portugal Visa application Centre London
Stack (most recent call last):
  File "/Users/kennethyellow/Documents/yellow/vfs-appointment-bot/vfs_appointment_bot/vfs_appointment_bot.py", line 50, in <module>
    logging.debug(e, exc_info=True, stack_info=True)
[2023-05-14 12:25:35,483] DEBUG [_ConfigReader.py root read_prop (13)]: twilio_to_num:to-number
[2023-05-14 12:25:35,483] DEBUG [_ConfigReader.py root read_prop (13)]: twilio_from_num:from-number
[2023-05-14 12:25:35,483] DEBUG [_ConfigReader.py root read_prop (13)]: twilio_account_sid:account-sid
[2023-05-14 12:25:35,483] DEBUG [_ConfigReader.py root read_prop (13)]: twilio_auth_token:auth-token
[2023-05-14 12:25:35,483] DEBUG [_ConfigReader.py root read_prop (13)]: twilio_url:twilio-url
[2023-05-14 12:25:35,483] DEBUG [_ConfigReader.py root read_bool_prop (18)]: twilio_sms_enabled:True
[2023-05-14 12:25:35,483] DEBUG [_ConfigReader.py root read_bool_prop (18)]: twilio_call_enabled:True
[2023-05-14 12:25:35,484] DEBUG [_ConfigReader.py root read_prop (13)]: chat_id:-1001941267897
[2023-05-14 12:25:35,484] DEBUG [_ConfigReader.py root read_prop (13)]: parse_mode:Markdown
[2023-05-14 12:25:35,484] DEBUG [_ConfigReader.py root read_prop (13)]: bot_token:6281742980:AAGIAXJlxLQhzvW4oveGtq9Y7bUxfXyf0Wc
[2023-05-14 12:25:35,484] DEBUG [_ConfigReader.py root read_prop (13)]: use_telegram:True
[2023-05-14 12:25:35,484] DEBUG [_ConfigReader.py root read_prop (13)]: use_twilio:False
[2023-05-14 12:25:35,484] DEBUG [_VfsClient.py root __init__ (25)]: Will use Telegram : True
[2023-05-14 12:25:35,484] DEBUG [_VfsClient.py root __init__ (26)]: Will use Twilio : False
[2023-05-14 12:25:35,484] DEBUG [_ConfigReader.py root read_prop (13)]: interval:120
[2023-05-14 12:25:35,484] DEBUG [vfs_appointment_bot.py __main__ <module> (37)]: Interval: 120
[2023-05-14 12:25:35,484] INFO [vfs_appointment_bot.py __main__ <module> (41)]: Starting VFS Appointment Bot
[2023-05-14 12:25:35,484] INFO [vfs_appointment_bot.py __main__ <module> (44)]: Running VFS Appointment Bot: Attempt#1
[2023-05-14 12:25:37,457] DEBUG [_ConfigReader.py root read_prop (13)]: vfs_login_url:https://visa.vfsglobal.com/gbr/en/prt/login
[2023-05-14 12:25:38,315] DEBUG [_ConfigReader.py root read_prop (13)]: vfs_email:zoe.connick@gmail.com
[2023-05-14 12:25:38,315] DEBUG [_ConfigReader.py root read_prop (13)]: vfs_password:Password1!2
[2023-05-14 12:25:38,315] DEBUG [_VfsClient.py root _login (54)]: Logging in with email: zoe.connick@gmail.com
[2023-05-14 12:25:58,658] DEBUG [_VfsClient.py root _validate_login (75)]: Logged in successfully
[2023-05-14 12:25:58,658] INFO [_VfsClient.py root _get_appointment_date (81)]: Getting appointment date: Visa Centre: Portugal Visa application Centre London, Category: Long Stay, Sub-Category: National Visa
[2023-05-14 12:26:06,153] INFO [vfs_appointment_bot.py __main__ <module> (49)]: Visa centre not found: Portugal Visa application Centre London. Please check the logs for more details
[2023-05-14 12:26:06,154] DEBUG [vfs_appointment_bot.py __main__ <module> (50)]: Visa centre not found: Portugal Visa application Centre London
Traceback (most recent call last):
  File "/Users/kennethyellow/Documents/yellow/vfs-appointment-bot/vfs_appointment_bot/_VfsClient.py", line 96, in _get_appointment_date
    _visa_centre = self._web_driver.find_element_by_xpath(
  File "/Users/kennethyellow/Documents/yellow/vfs-appointment-bot/venv/lib/python3.9/site-packages/selenium/webdriver/remote/webdriver.py", line 394, in find_element_by_xpath
    return self.find_element(by=By.XPATH, value=xpath)
  File "/Users/kennethyellow/Documents/yellow/vfs-appointment-bot/venv/lib/python3.9/site-packages/selenium/webdriver/remote/webdriver.py", line 976, in find_element
    return self.execute(Command.FIND_ELEMENT, {
  File "/Users/kennethyellow/Documents/yellow/vfs-appointment-bot/venv/lib/python3.9/site-packages/selenium/webdriver/remote/webdriver.py", line 321, in execute
    self.error_handler.check_response(response)
  File "/Users/kennethyellow/Documents/yellow/vfs-appointment-bot/venv/lib/python3.9/site-packages/selenium/webdriver/remote/errorhandler.py", line 242, in check_response
    raise exception_class(message, screen, stacktrace)
selenium.common.exceptions.NoSuchElementException: Message: Unable to locate element: //mat-option[starts-with(@id,'mat-option-')]/span[contains(text(), 'Portugal Visa application Centre London')]


During handling of the above exception, another exception occurred:

Traceback (most recent call last):
  File "/Users/kennethyellow/Documents/yellow/vfs-appointment-bot/vfs_appointment_bot/vfs_appointment_bot.py", line 45, in <module>
    _vfs_client.check_slot(visa_centre=visa_centre, category=category, sub_category=sub_category)
  File "/Users/kennethyellow/Documents/yellow/vfs-appointment-bot/vfs_appointment_bot/_VfsClient.py", line 156, in check_slot
    _message = self._get_appointment_date(visa_centre, category, sub_category)
  File "/Users/kennethyellow/Documents/yellow/vfs-appointment-bot/vfs_appointment_bot/_VfsClient.py", line 102, in _get_appointment_date
    raise Exception("Visa centre not found: {}".format(visa_centre))
Exception: Visa centre not found: Portugal Visa application Centre London
Stack (most recent call last):
  File "/Users/kennethyellow/Documents/yellow/vfs-appointment-bot/vfs_appointment_bot/vfs_appointment_bot.py", line 50, in <module>
    logging.debug(e, exc_info=True, stack_info=True)
[2023-05-14 12:27:49,533] DEBUG [_ConfigReader.py root read_prop (13)]: twilio_to_num:to-number
[2023-05-14 12:27:49,533] DEBUG [_ConfigReader.py root read_prop (13)]: twilio_from_num:from-number
[2023-05-14 12:27:49,533] DEBUG [_ConfigReader.py root read_prop (13)]: twilio_account_sid:account-sid
[2023-05-14 12:27:49,533] DEBUG [_ConfigReader.py root read_prop (13)]: twilio_auth_token:auth-token
[2023-05-14 12:27:49,533] DEBUG [_ConfigReader.py root read_prop (13)]: twilio_url:twilio-url
[2023-05-14 12:27:49,533] DEBUG [_ConfigReader.py root read_bool_prop (18)]: twilio_sms_enabled:True
[2023-05-14 12:27:49,533] DEBUG [_ConfigReader.py root read_bool_prop (18)]: twilio_call_enabled:True
[2023-05-14 12:27:49,533] DEBUG [_ConfigReader.py root read_prop (13)]: chat_id:-1001941267897
[2023-05-14 12:27:49,533] DEBUG [_ConfigReader.py root read_prop (13)]: parse_mode:Markdown
[2023-05-14 12:27:49,533] DEBUG [_ConfigReader.py root read_prop (13)]: bot_token:6281742980:AAGIAXJlxLQhzvW4oveGtq9Y7bUxfXyf0Wc
[2023-05-14 12:27:49,533] DEBUG [_ConfigReader.py root read_prop (13)]: use_telegram:True
[2023-05-14 12:27:49,533] DEBUG [_ConfigReader.py root read_prop (13)]: use_twilio:False
[2023-05-14 12:27:49,533] DEBUG [_VfsClient.py root __init__ (25)]: Will use Telegram : True
[2023-05-14 12:27:49,533] DEBUG [_VfsClient.py root __init__ (26)]: Will use Twilio : False
[2023-05-14 12:27:49,533] DEBUG [_ConfigReader.py root read_prop (13)]: interval:120
[2023-05-14 12:27:49,533] DEBUG [vfs_appointment_bot.py __main__ <module> (37)]: Interval: 120
[2023-05-14 12:27:49,533] INFO [vfs_appointment_bot.py __main__ <module> (41)]: Starting VFS Appointment Bot
[2023-05-14 12:27:49,533] INFO [vfs_appointment_bot.py __main__ <module> (44)]: Running VFS Appointment Bot: Attempt#1
[2023-05-14 12:27:51,440] DEBUG [_ConfigReader.py root read_prop (13)]: vfs_login_url:https://visa.vfsglobal.com/gbr/en/prt/login
[2023-05-14 12:27:52,492] DEBUG [_ConfigReader.py root read_prop (13)]: vfs_email:zoe.connick@gmail.com
[2023-05-14 12:27:52,492] DEBUG [_ConfigReader.py root read_prop (13)]: vfs_password:Password1!2
[2023-05-14 12:27:52,492] DEBUG [_VfsClient.py root _login (54)]: Logging in with email: zoe.connick@gmail.com
[2023-05-14 12:28:12,829] DEBUG [_VfsClient.py root _validate_login (75)]: Logged in successfully
[2023-05-14 12:28:12,829] INFO [_VfsClient.py root _get_appointment_date (81)]: Getting appointment date: Visa Centre: Portugal Visa application Centre London, Category: Long Stay, Sub-Category: National Visa
[2023-05-14 12:28:20,320] INFO [vfs_appointment_bot.py __main__ <module> (49)]: local variable 'option' referenced before assignment. Please check the logs for more details
[2023-05-14 12:28:20,321] DEBUG [vfs_appointment_bot.py __main__ <module> (50)]: local variable 'option' referenced before assignment
Traceback (most recent call last):
  File "/Users/kennethyellow/Documents/yellow/vfs-appointment-bot/vfs_appointment_bot/_VfsClient.py", line 96, in _get_appointment_date
    _visa_centre = self._web_driver.find_element_by_xpath(
  File "/Users/kennethyellow/Documents/yellow/vfs-appointment-bot/venv/lib/python3.9/site-packages/selenium/webdriver/remote/webdriver.py", line 394, in find_element_by_xpath
    return self.find_element(by=By.XPATH, value=xpath)
  File "/Users/kennethyellow/Documents/yellow/vfs-appointment-bot/venv/lib/python3.9/site-packages/selenium/webdriver/remote/webdriver.py", line 976, in find_element
    return self.execute(Command.FIND_ELEMENT, {
  File "/Users/kennethyellow/Documents/yellow/vfs-appointment-bot/venv/lib/python3.9/site-packages/selenium/webdriver/remote/webdriver.py", line 321, in execute
    self.error_handler.check_response(response)
  File "/Users/kennethyellow/Documents/yellow/vfs-appointment-bot/venv/lib/python3.9/site-packages/selenium/webdriver/remote/errorhandler.py", line 242, in check_response
    raise exception_class(message, screen, stacktrace)
selenium.common.exceptions.NoSuchElementException: Message: Unable to locate element: //mat-option[starts-with(@id,'mat-option-')]/span[contains(text(), 'Portugal Visa application Centre London')]


During handling of the above exception, another exception occurred:

Traceback (most recent call last):
  File "/Users/kennethyellow/Documents/yellow/vfs-appointment-bot/vfs_appointment_bot/vfs_appointment_bot.py", line 45, in <module>
    _vfs_client.check_slot(visa_centre=visa_centre, category=category, sub_category=sub_category)
  File "/Users/kennethyellow/Documents/yellow/vfs-appointment-bot/vfs_appointment_bot/_VfsClient.py", line 156, in check_slot
    _message = self._get_appointment_date(visa_centre, category, sub_category)
  File "/Users/kennethyellow/Documents/yellow/vfs-appointment-bot/vfs_appointment_bot/_VfsClient.py", line 102, in _get_appointment_date
    raise Exception("Visa centre not found: {}".format(option.text))
UnboundLocalError: local variable 'option' referenced before assignment
Stack (most recent call last):
  File "/Users/kennethyellow/Documents/yellow/vfs-appointment-bot/vfs_appointment_bot/vfs_appointment_bot.py", line 50, in <module>
    logging.debug(e, exc_info=True, stack_info=True)
[2023-05-14 12:29:22,428] DEBUG [_ConfigReader.py root read_prop (13)]: twilio_to_num:to-number
[2023-05-14 12:29:22,428] DEBUG [_ConfigReader.py root read_prop (13)]: twilio_from_num:from-number
[2023-05-14 12:29:22,428] DEBUG [_ConfigReader.py root read_prop (13)]: twilio_account_sid:account-sid
[2023-05-14 12:29:22,428] DEBUG [_ConfigReader.py root read_prop (13)]: twilio_auth_token:auth-token
[2023-05-14 12:29:22,428] DEBUG [_ConfigReader.py root read_prop (13)]: twilio_url:twilio-url
[2023-05-14 12:29:22,428] DEBUG [_ConfigReader.py root read_bool_prop (18)]: twilio_sms_enabled:True
[2023-05-14 12:29:22,428] DEBUG [_ConfigReader.py root read_bool_prop (18)]: twilio_call_enabled:True
[2023-05-14 12:29:22,428] DEBUG [_ConfigReader.py root read_prop (13)]: chat_id:-1001941267897
[2023-05-14 12:29:22,428] DEBUG [_ConfigReader.py root read_prop (13)]: parse_mode:Markdown
[2023-05-14 12:29:22,428] DEBUG [_ConfigReader.py root read_prop (13)]: bot_token:6281742980:AAGIAXJlxLQhzvW4oveGtq9Y7bUxfXyf0Wc
[2023-05-14 12:29:22,428] DEBUG [_ConfigReader.py root read_prop (13)]: use_telegram:True
[2023-05-14 12:29:22,428] DEBUG [_ConfigReader.py root read_prop (13)]: use_twilio:False
[2023-05-14 12:29:22,428] DEBUG [_VfsClient.py root __init__ (25)]: Will use Telegram : True
[2023-05-14 12:29:22,428] DEBUG [_VfsClient.py root __init__ (26)]: Will use Twilio : False
[2023-05-14 12:29:22,428] DEBUG [_ConfigReader.py root read_prop (13)]: interval:120
[2023-05-14 12:29:22,429] DEBUG [vfs_appointment_bot.py __main__ <module> (37)]: Interval: 120
[2023-05-14 12:29:22,429] INFO [vfs_appointment_bot.py __main__ <module> (41)]: Starting VFS Appointment Bot
[2023-05-14 12:29:22,429] INFO [vfs_appointment_bot.py __main__ <module> (44)]: Running VFS Appointment Bot: Attempt#1
[2023-05-14 12:29:24,349] DEBUG [_ConfigReader.py root read_prop (13)]: vfs_login_url:https://visa.vfsglobal.com/gbr/en/prt/login
[2023-05-14 12:29:25,114] DEBUG [_ConfigReader.py root read_prop (13)]: vfs_email:zoe.connick@gmail.com
[2023-05-14 12:29:25,114] DEBUG [_ConfigReader.py root read_prop (13)]: vfs_password:Password1!2
[2023-05-14 12:29:25,115] DEBUG [_VfsClient.py root _login (54)]: Logging in with email: zoe.connick@gmail.com
[2023-05-14 12:29:45,456] DEBUG [_VfsClient.py root _validate_login (75)]: Logged in successfully
[2023-05-14 12:29:45,456] INFO [_VfsClient.py root _get_appointment_date (81)]: Getting appointment date: Visa Centre: Portugal Visa application Centre London, Category: Long Stay, Sub-Category: National Visa
[2023-05-14 12:29:52,923] INFO [vfs_appointment_bot.py __main__ <module> (49)]: Visa centre not found: Portugal Visa application Centre London. Please check the logs for more details
[2023-05-14 12:29:52,924] DEBUG [vfs_appointment_bot.py __main__ <module> (50)]: Visa centre not found: Portugal Visa application Centre London
Traceback (most recent call last):
  File "/Users/kennethyellow/Documents/yellow/vfs-appointment-bot/vfs_appointment_bot/_VfsClient.py", line 97, in _get_appointment_date
    _visa_centre = self._web_driver.find_element_by_xpath(
  File "/Users/kennethyellow/Documents/yellow/vfs-appointment-bot/venv/lib/python3.9/site-packages/selenium/webdriver/remote/webdriver.py", line 394, in find_element_by_xpath
    return self.find_element(by=By.XPATH, value=xpath)
  File "/Users/kennethyellow/Documents/yellow/vfs-appointment-bot/venv/lib/python3.9/site-packages/selenium/webdriver/remote/webdriver.py", line 976, in find_element
    return self.execute(Command.FIND_ELEMENT, {
  File "/Users/kennethyellow/Documents/yellow/vfs-appointment-bot/venv/lib/python3.9/site-packages/selenium/webdriver/remote/webdriver.py", line 321, in execute
    self.error_handler.check_response(response)
  File "/Users/kennethyellow/Documents/yellow/vfs-appointment-bot/venv/lib/python3.9/site-packages/selenium/webdriver/remote/errorhandler.py", line 242, in check_response
    raise exception_class(message, screen, stacktrace)
selenium.common.exceptions.NoSuchElementException: Message: Unable to locate element: //mat-option[starts-with(@id,'mat-option-')]/span[contains(text(), 'Portugal Visa application Centre London')]


During handling of the above exception, another exception occurred:

Traceback (most recent call last):
  File "/Users/kennethyellow/Documents/yellow/vfs-appointment-bot/vfs_appointment_bot/vfs_appointment_bot.py", line 45, in <module>
    _vfs_client.check_slot(visa_centre=visa_centre, category=category, sub_category=sub_category)
  File "/Users/kennethyellow/Documents/yellow/vfs-appointment-bot/vfs_appointment_bot/_VfsClient.py", line 155, in check_slot
    _message = self._get_appointment_date(visa_centre, category, sub_category)
  File "/Users/kennethyellow/Documents/yellow/vfs-appointment-bot/vfs_appointment_bot/_VfsClient.py", line 101, in _get_appointment_date
    raise Exception("Visa centre not found: {}".format(visa_centre))
Exception: Visa centre not found: Portugal Visa application Centre London
Stack (most recent call last):
  File "/Users/kennethyellow/Documents/yellow/vfs-appointment-bot/vfs_appointment_bot/vfs_appointment_bot.py", line 50, in <module>
    logging.debug(e, exc_info=True, stack_info=True)
[2023-05-14 12:45:06,167] DEBUG [_ConfigReader.py root read_prop (13)]: twilio_to_num:to-number
[2023-05-14 12:45:06,167] DEBUG [_ConfigReader.py root read_prop (13)]: twilio_from_num:from-number
[2023-05-14 12:45:06,167] DEBUG [_ConfigReader.py root read_prop (13)]: twilio_account_sid:account-sid
[2023-05-14 12:45:06,167] DEBUG [_ConfigReader.py root read_prop (13)]: twilio_auth_token:auth-token
[2023-05-14 12:45:06,167] DEBUG [_ConfigReader.py root read_prop (13)]: twilio_url:twilio-url
[2023-05-14 12:45:06,167] DEBUG [_ConfigReader.py root read_bool_prop (18)]: twilio_sms_enabled:True
[2023-05-14 12:45:06,167] DEBUG [_ConfigReader.py root read_bool_prop (18)]: twilio_call_enabled:True
[2023-05-14 12:45:06,167] DEBUG [_ConfigReader.py root read_prop (13)]: chat_id:-1001941267897
[2023-05-14 12:45:06,167] DEBUG [_ConfigReader.py root read_prop (13)]: parse_mode:Markdown
[2023-05-14 12:45:06,167] DEBUG [_ConfigReader.py root read_prop (13)]: bot_token:6281742980:AAGIAXJlxLQhzvW4oveGtq9Y7bUxfXyf0Wc
[2023-05-14 12:45:06,167] DEBUG [_ConfigReader.py root read_prop (13)]: use_telegram:True
[2023-05-14 12:45:06,167] DEBUG [_ConfigReader.py root read_prop (13)]: use_twilio:False
[2023-05-14 12:45:06,168] DEBUG [_VfsClient.py root __init__ (25)]: Will use Telegram : True
[2023-05-14 12:45:06,168] DEBUG [_VfsClient.py root __init__ (26)]: Will use Twilio : False
[2023-05-14 12:45:06,168] DEBUG [_ConfigReader.py root read_prop (13)]: interval:120
[2023-05-14 12:45:06,168] DEBUG [vfs_appointment_bot.py __main__ <module> (37)]: Interval: 120
[2023-05-14 12:45:06,168] INFO [vfs_appointment_bot.py __main__ <module> (41)]: Starting VFS Appointment Bot
[2023-05-14 12:45:06,168] INFO [vfs_appointment_bot.py __main__ <module> (44)]: Running VFS Appointment Bot: Attempt#1
[2023-05-14 12:45:08,111] DEBUG [_ConfigReader.py root read_prop (13)]: vfs_login_url:https://visa.vfsglobal.com/gbr/en/prt/login
[2023-05-14 12:45:09,097] DEBUG [_ConfigReader.py root read_prop (13)]: vfs_email:zoe.connick@gmail.com
[2023-05-14 12:45:09,097] DEBUG [_ConfigReader.py root read_prop (13)]: vfs_password:Password1!2
[2023-05-14 12:45:09,097] DEBUG [_VfsClient.py root _login (54)]: Logging in with email: zoe.connick@gmail.com
[2023-05-14 12:45:29,432] DEBUG [_VfsClient.py root _validate_login (75)]: Logged in successfully
[2023-05-14 12:45:29,432] INFO [_VfsClient.py root _get_appointment_date (81)]: Getting appointment date: Visa Centre: Portugal Visa application Centre London, Category: Long Stay, Sub-Category: National Visa
[2023-05-14 12:45:29,436] INFO [vfs_appointment_bot.py __main__ <module> (49)]: Unable to locate element: /html/body/app-root/div/app-dashboard/section[1]/div/div[2]/button. Please check the logs for more details
[2023-05-14 12:45:29,438] DEBUG [vfs_appointment_bot.py __main__ <module> (50)]: Message: Unable to locate element: /html/body/app-root/div/app-dashboard/section[1]/div/div[2]/button
Traceback (most recent call last):
  File "/Users/kennethyellow/Documents/yellow/vfs-appointment-bot/vfs_appointment_bot/vfs_appointment_bot.py", line 45, in <module>
    _vfs_client.check_slot(visa_centre=visa_centre, category=category, sub_category=sub_category)
  File "/Users/kennethyellow/Documents/yellow/vfs-appointment-bot/vfs_appointment_bot/_VfsClient.py", line 154, in check_slot
    _message = self._get_appointment_date(visa_centre, category, sub_category)
  File "/Users/kennethyellow/Documents/yellow/vfs-appointment-bot/vfs_appointment_bot/_VfsClient.py", line 83, in _get_appointment_date
    _new_booking_button = self._web_driver.find_element_by_xpath(
  File "/Users/kennethyellow/Documents/yellow/vfs-appointment-bot/venv/lib/python3.9/site-packages/selenium/webdriver/remote/webdriver.py", line 394, in find_element_by_xpath
    return self.find_element(by=By.XPATH, value=xpath)
  File "/Users/kennethyellow/Documents/yellow/vfs-appointment-bot/venv/lib/python3.9/site-packages/selenium/webdriver/remote/webdriver.py", line 976, in find_element
    return self.execute(Command.FIND_ELEMENT, {
  File "/Users/kennethyellow/Documents/yellow/vfs-appointment-bot/venv/lib/python3.9/site-packages/selenium/webdriver/remote/webdriver.py", line 321, in execute
    self.error_handler.check_response(response)
  File "/Users/kennethyellow/Documents/yellow/vfs-appointment-bot/venv/lib/python3.9/site-packages/selenium/webdriver/remote/errorhandler.py", line 242, in check_response
    raise exception_class(message, screen, stacktrace)
selenium.common.exceptions.NoSuchElementException: Message: Unable to locate element: /html/body/app-root/div/app-dashboard/section[1]/div/div[2]/button
Stack (most recent call last):
  File "/Users/kennethyellow/Documents/yellow/vfs-appointment-bot/vfs_appointment_bot/vfs_appointment_bot.py", line 50, in <module>
    logging.debug(e, exc_info=True, stack_info=True)
[2023-05-14 12:46:30,680] INFO [vfs_appointment_bot.py __main__ <module> (44)]: Running VFS Appointment Bot: Attempt#2
[2023-05-14 12:46:32,616] DEBUG [_ConfigReader.py root read_prop (13)]: vfs_login_url:https://visa.vfsglobal.com/gbr/en/prt/login
[2023-05-14 12:46:33,655] DEBUG [_ConfigReader.py root read_prop (13)]: vfs_email:zoe.connick@gmail.com
[2023-05-14 12:46:33,655] DEBUG [_ConfigReader.py root read_prop (13)]: vfs_password:Password1!2
[2023-05-14 12:46:33,655] DEBUG [_VfsClient.py root _login (54)]: Logging in with email: zoe.connick@gmail.com
[2023-05-14 12:46:53,999] DEBUG [_VfsClient.py root _validate_login (75)]: Logged in successfully
[2023-05-14 12:46:54,000] INFO [_VfsClient.py root _get_appointment_date (81)]: Getting appointment date: Visa Centre: Portugal Visa application Centre London, Category: Long Stay, Sub-Category: National Visa
[2023-05-14 12:46:54,004] INFO [vfs_appointment_bot.py __main__ <module> (49)]: Unable to locate element: /html/body/app-root/div/app-dashboard/section[1]/div/div[2]/button. Please check the logs for more details
[2023-05-14 12:46:54,004] DEBUG [vfs_appointment_bot.py __main__ <module> (50)]: Message: Unable to locate element: /html/body/app-root/div/app-dashboard/section[1]/div/div[2]/button
Traceback (most recent call last):
  File "/Users/kennethyellow/Documents/yellow/vfs-appointment-bot/vfs_appointment_bot/vfs_appointment_bot.py", line 45, in <module>
    _vfs_client.check_slot(visa_centre=visa_centre, category=category, sub_category=sub_category)
  File "/Users/kennethyellow/Documents/yellow/vfs-appointment-bot/vfs_appointment_bot/_VfsClient.py", line 154, in check_slot
    _message = self._get_appointment_date(visa_centre, category, sub_category)
  File "/Users/kennethyellow/Documents/yellow/vfs-appointment-bot/vfs_appointment_bot/_VfsClient.py", line 83, in _get_appointment_date
    _new_booking_button = self._web_driver.find_element_by_xpath(
  File "/Users/kennethyellow/Documents/yellow/vfs-appointment-bot/venv/lib/python3.9/site-packages/selenium/webdriver/remote/webdriver.py", line 394, in find_element_by_xpath
    return self.find_element(by=By.XPATH, value=xpath)
  File "/Users/kennethyellow/Documents/yellow/vfs-appointment-bot/venv/lib/python3.9/site-packages/selenium/webdriver/remote/webdriver.py", line 976, in find_element
    return self.execute(Command.FIND_ELEMENT, {
  File "/Users/kennethyellow/Documents/yellow/vfs-appointment-bot/venv/lib/python3.9/site-packages/selenium/webdriver/remote/webdriver.py", line 321, in execute
    self.error_handler.check_response(response)
  File "/Users/kennethyellow/Documents/yellow/vfs-appointment-bot/venv/lib/python3.9/site-packages/selenium/webdriver/remote/errorhandler.py", line 242, in check_response
    raise exception_class(message, screen, stacktrace)
selenium.common.exceptions.NoSuchElementException: Message: Unable to locate element: /html/body/app-root/div/app-dashboard/section[1]/div/div[2]/button
Stack (most recent call last):
  File "/Users/kennethyellow/Documents/yellow/vfs-appointment-bot/vfs_appointment_bot/vfs_appointment_bot.py", line 50, in <module>
    logging.debug(e, exc_info=True, stack_info=True)
[2023-05-14 12:47:55,235] INFO [vfs_appointment_bot.py __main__ <module> (44)]: Running VFS Appointment Bot: Attempt#3
[2023-05-14 12:47:57,152] DEBUG [_ConfigReader.py root read_prop (13)]: vfs_login_url:https://visa.vfsglobal.com/gbr/en/prt/login
[2023-05-14 12:47:57,955] DEBUG [_ConfigReader.py root read_prop (13)]: vfs_email:zoe.connick@gmail.com
[2023-05-14 12:47:57,955] DEBUG [_ConfigReader.py root read_prop (13)]: vfs_password:Password1!2
[2023-05-14 12:47:57,955] DEBUG [_VfsClient.py root _login (54)]: Logging in with email: zoe.connick@gmail.com
[2023-05-14 12:48:18,283] DEBUG [_VfsClient.py root _validate_login (75)]: Logged in successfully
[2023-05-14 12:48:18,283] INFO [_VfsClient.py root _get_appointment_date (81)]: Getting appointment date: Visa Centre: Portugal Visa application Centre London, Category: Long Stay, Sub-Category: National Visa
[2023-05-14 12:48:18,287] INFO [vfs_appointment_bot.py __main__ <module> (49)]: Unable to locate element: /html/body/app-root/div/app-dashboard/section[1]/div/div[2]/button. Please check the logs for more details
[2023-05-14 12:48:18,287] DEBUG [vfs_appointment_bot.py __main__ <module> (50)]: Message: Unable to locate element: /html/body/app-root/div/app-dashboard/section[1]/div/div[2]/button
Traceback (most recent call last):
  File "/Users/kennethyellow/Documents/yellow/vfs-appointment-bot/vfs_appointment_bot/vfs_appointment_bot.py", line 45, in <module>
    _vfs_client.check_slot(visa_centre=visa_centre, category=category, sub_category=sub_category)
  File "/Users/kennethyellow/Documents/yellow/vfs-appointment-bot/vfs_appointment_bot/_VfsClient.py", line 154, in check_slot
    _message = self._get_appointment_date(visa_centre, category, sub_category)
  File "/Users/kennethyellow/Documents/yellow/vfs-appointment-bot/vfs_appointment_bot/_VfsClient.py", line 83, in _get_appointment_date
    _new_booking_button = self._web_driver.find_element_by_xpath(
  File "/Users/kennethyellow/Documents/yellow/vfs-appointment-bot/venv/lib/python3.9/site-packages/selenium/webdriver/remote/webdriver.py", line 394, in find_element_by_xpath
    return self.find_element(by=By.XPATH, value=xpath)
  File "/Users/kennethyellow/Documents/yellow/vfs-appointment-bot/venv/lib/python3.9/site-packages/selenium/webdriver/remote/webdriver.py", line 976, in find_element
    return self.execute(Command.FIND_ELEMENT, {
  File "/Users/kennethyellow/Documents/yellow/vfs-appointment-bot/venv/lib/python3.9/site-packages/selenium/webdriver/remote/webdriver.py", line 321, in execute
    self.error_handler.check_response(response)
  File "/Users/kennethyellow/Documents/yellow/vfs-appointment-bot/venv/lib/python3.9/site-packages/selenium/webdriver/remote/errorhandler.py", line 242, in check_response
    raise exception_class(message, screen, stacktrace)
selenium.common.exceptions.NoSuchElementException: Message: Unable to locate element: /html/body/app-root/div/app-dashboard/section[1]/div/div[2]/button
Stack (most recent call last):
  File "/Users/kennethyellow/Documents/yellow/vfs-appointment-bot/vfs_appointment_bot/vfs_appointment_bot.py", line 50, in <module>
    logging.debug(e, exc_info=True, stack_info=True)
[2023-05-14 12:49:19,510] INFO [vfs_appointment_bot.py __main__ <module> (44)]: Running VFS Appointment Bot: Attempt#4
[2023-05-14 12:49:21,410] DEBUG [_ConfigReader.py root read_prop (13)]: vfs_login_url:https://visa.vfsglobal.com/gbr/en/prt/login
[2023-05-14 12:49:22,166] DEBUG [_ConfigReader.py root read_prop (13)]: vfs_email:zoe.connick@gmail.com
[2023-05-14 12:49:22,166] DEBUG [_ConfigReader.py root read_prop (13)]: vfs_password:Password1!2
[2023-05-14 12:49:22,166] DEBUG [_VfsClient.py root _login (54)]: Logging in with email: zoe.connick@gmail.com
[2023-05-14 12:49:42,504] DEBUG [_VfsClient.py root _validate_login (75)]: Logged in successfully
[2023-05-14 12:49:42,505] INFO [_VfsClient.py root _get_appointment_date (81)]: Getting appointment date: Visa Centre: Portugal Visa application Centre London, Category: Long Stay, Sub-Category: National Visa
[2023-05-14 12:49:42,508] INFO [vfs_appointment_bot.py __main__ <module> (49)]: Unable to locate element: /html/body/app-root/div/app-dashboard/section[1]/div/div[2]/button. Please check the logs for more details
[2023-05-14 12:49:42,509] DEBUG [vfs_appointment_bot.py __main__ <module> (50)]: Message: Unable to locate element: /html/body/app-root/div/app-dashboard/section[1]/div/div[2]/button
Traceback (most recent call last):
  File "/Users/kennethyellow/Documents/yellow/vfs-appointment-bot/vfs_appointment_bot/vfs_appointment_bot.py", line 45, in <module>
    _vfs_client.check_slot(visa_centre=visa_centre, category=category, sub_category=sub_category)
  File "/Users/kennethyellow/Documents/yellow/vfs-appointment-bot/vfs_appointment_bot/_VfsClient.py", line 154, in check_slot
    _message = self._get_appointment_date(visa_centre, category, sub_category)
  File "/Users/kennethyellow/Documents/yellow/vfs-appointment-bot/vfs_appointment_bot/_VfsClient.py", line 83, in _get_appointment_date
    _new_booking_button = self._web_driver.find_element_by_xpath(
  File "/Users/kennethyellow/Documents/yellow/vfs-appointment-bot/venv/lib/python3.9/site-packages/selenium/webdriver/remote/webdriver.py", line 394, in find_element_by_xpath
    return self.find_element(by=By.XPATH, value=xpath)
  File "/Users/kennethyellow/Documents/yellow/vfs-appointment-bot/venv/lib/python3.9/site-packages/selenium/webdriver/remote/webdriver.py", line 976, in find_element
    return self.execute(Command.FIND_ELEMENT, {
  File "/Users/kennethyellow/Documents/yellow/vfs-appointment-bot/venv/lib/python3.9/site-packages/selenium/webdriver/remote/webdriver.py", line 321, in execute
    self.error_handler.check_response(response)
  File "/Users/kennethyellow/Documents/yellow/vfs-appointment-bot/venv/lib/python3.9/site-packages/selenium/webdriver/remote/errorhandler.py", line 242, in check_response
    raise exception_class(message, screen, stacktrace)
selenium.common.exceptions.NoSuchElementException: Message: Unable to locate element: /html/body/app-root/div/app-dashboard/section[1]/div/div[2]/button
Stack (most recent call last):
  File "/Users/kennethyellow/Documents/yellow/vfs-appointment-bot/vfs_appointment_bot/vfs_appointment_bot.py", line 50, in <module>
    logging.debug(e, exc_info=True, stack_info=True)
[2023-05-14 12:50:43,879] INFO [vfs_appointment_bot.py __main__ <module> (44)]: Running VFS Appointment Bot: Attempt#5
[2023-05-14 12:50:45,814] DEBUG [_ConfigReader.py root read_prop (13)]: vfs_login_url:https://visa.vfsglobal.com/gbr/en/prt/login
[2023-05-14 12:50:46,822] DEBUG [_ConfigReader.py root read_prop (13)]: vfs_email:zoe.connick@gmail.com
[2023-05-14 12:50:46,822] DEBUG [_ConfigReader.py root read_prop (13)]: vfs_password:Password1!2
[2023-05-14 12:50:46,822] DEBUG [_VfsClient.py root _login (54)]: Logging in with email: zoe.connick@gmail.com
[2023-05-14 12:54:15,813] DEBUG [_ConfigReader.py root read_prop (13)]: twilio_to_num:to-number
[2023-05-14 12:54:15,813] DEBUG [_ConfigReader.py root read_prop (13)]: twilio_from_num:from-number
[2023-05-14 12:54:15,814] DEBUG [_ConfigReader.py root read_prop (13)]: twilio_account_sid:account-sid
[2023-05-14 12:54:15,814] DEBUG [_ConfigReader.py root read_prop (13)]: twilio_auth_token:auth-token
[2023-05-14 12:54:15,814] DEBUG [_ConfigReader.py root read_prop (13)]: twilio_url:twilio-url
[2023-05-14 12:54:15,814] DEBUG [_ConfigReader.py root read_bool_prop (18)]: twilio_sms_enabled:True
[2023-05-14 12:54:15,814] DEBUG [_ConfigReader.py root read_bool_prop (18)]: twilio_call_enabled:True
[2023-05-14 12:54:16,210] DEBUG [_ConfigReader.py root read_prop (13)]: chat_id:-1001941267897
[2023-05-14 12:54:16,210] DEBUG [_ConfigReader.py root read_prop (13)]: parse_mode:Markdown
[2023-05-14 12:54:16,210] DEBUG [_ConfigReader.py root read_prop (13)]: bot_token:6281742980:AAGIAXJlxLQhzvW4oveGtq9Y7bUxfXyf0Wc
[2023-05-14 12:54:17,000] DEBUG [_ConfigReader.py root read_prop (13)]: use_telegram:True
[2023-05-14 12:54:17,470] DEBUG [_ConfigReader.py root read_prop (13)]: use_twilio:False
[2023-05-14 12:54:17,844] DEBUG [_VfsClient.py root __init__ (25)]: Will use Telegram : True
[2023-05-14 12:54:18,195] DEBUG [_VfsClient.py root __init__ (26)]: Will use Twilio : False
[2023-05-14 12:54:23,723] DEBUG [_ConfigReader.py root read_prop (13)]: interval:120
[2023-05-14 12:54:24,373] DEBUG [vfs_appointment_bot.py __main__ <module> (37)]: Interval: 120
[2023-05-14 12:55:51,339] DEBUG [vfs_appointment_bot.py __main__ _input (19)]: Visa centre: Portugal Visa application Centre London, Category: Long Stay, Sub-Category: National Visa
[2023-05-14 12:56:07,616] INFO [vfs_appointment_bot.py __main__ <module> (41)]: Starting VFS Appointment Bot
[2023-05-14 12:56:10,412] INFO [vfs_appointment_bot.py __main__ <module> (44)]: Running VFS Appointment Bot: Attempt#1
[2023-05-14 12:56:12,937] DEBUG [_ConfigReader.py root read_prop (13)]: vfs_login_url:https://visa.vfsglobal.com/gbr/en/prt/login
[2023-05-14 12:56:13,869] DEBUG [_ConfigReader.py root read_prop (13)]: vfs_email:zoe.connick@gmail.com
[2023-05-14 12:56:13,869] DEBUG [_ConfigReader.py root read_prop (13)]: vfs_password:Password1!2
[2023-05-14 12:56:13,869] DEBUG [_VfsClient.py root _login (54)]: Logging in with email: zoe.connick@gmail.com
[2023-05-14 12:57:24,546] DEBUG [_VfsClient.py root _validate_login (75)]: Logged in successfully
[2023-05-14 12:57:30,499] INFO [_VfsClient.py root _get_appointment_date (81)]: Getting appointment date: Visa Centre: Portugal Visa application Centre London, Category: Long Stay, Sub-Category: National Visa
[2023-05-14 12:59:55,639] DEBUG [_ConfigReader.py root read_prop (13)]: twilio_to_num:to-number
[2023-05-14 12:59:55,640] DEBUG [_ConfigReader.py root read_prop (13)]: twilio_from_num:from-number
[2023-05-14 12:59:55,640] DEBUG [_ConfigReader.py root read_prop (13)]: twilio_account_sid:account-sid
[2023-05-14 12:59:55,640] DEBUG [_ConfigReader.py root read_prop (13)]: twilio_auth_token:auth-token
[2023-05-14 12:59:55,640] DEBUG [_ConfigReader.py root read_prop (13)]: twilio_url:twilio-url
[2023-05-14 12:59:55,640] DEBUG [_ConfigReader.py root read_bool_prop (18)]: twilio_sms_enabled:True
[2023-05-14 12:59:55,641] DEBUG [_ConfigReader.py root read_bool_prop (18)]: twilio_call_enabled:True
[2023-05-14 12:59:55,641] DEBUG [_ConfigReader.py root read_prop (13)]: chat_id:-1001941267897
[2023-05-14 12:59:55,641] DEBUG [_ConfigReader.py root read_prop (13)]: parse_mode:Markdown
[2023-05-14 12:59:55,642] DEBUG [_ConfigReader.py root read_prop (13)]: bot_token:6281742980:AAGIAXJlxLQhzvW4oveGtq9Y7bUxfXyf0Wc
[2023-05-14 12:59:55,642] DEBUG [_ConfigReader.py root read_prop (13)]: use_telegram:True
[2023-05-14 12:59:55,642] DEBUG [_ConfigReader.py root read_prop (13)]: use_twilio:False
[2023-05-14 12:59:55,643] DEBUG [_VfsClient.py root __init__ (25)]: Will use Telegram : True
[2023-05-14 12:59:55,643] DEBUG [_VfsClient.py root __init__ (26)]: Will use Twilio : False
[2023-05-14 12:59:55,643] DEBUG [_ConfigReader.py root read_prop (13)]: interval:120
[2023-05-14 12:59:55,643] DEBUG [vfs_appointment_bot.py __main__ <module> (37)]: Interval: 120
[2023-05-14 13:02:58,858] DEBUG [vfs_appointment_bot.py __main__ _input (19)]: Visa centre: Portugal Visa application Centre London, Category: National Visa, Sub-Category: Long Stay
[2023-05-14 13:02:58,861] INFO [vfs_appointment_bot.py __main__ <module> (41)]: Starting VFS Appointment Bot
[2023-05-14 13:02:58,861] INFO [vfs_appointment_bot.py __main__ <module> (44)]: Running VFS Appointment Bot: Attempt#1
[2023-05-14 13:03:00,806] DEBUG [_ConfigReader.py root read_prop (13)]: vfs_login_url:https://visa.vfsglobal.com/gbr/en/prt/login
[2023-05-14 13:03:01,571] DEBUG [_ConfigReader.py root read_prop (13)]: vfs_email:zoe.connick@gmail.com
[2023-05-14 13:03:01,571] DEBUG [_ConfigReader.py root read_prop (13)]: vfs_password:Password1!2
[2023-05-14 13:03:01,571] DEBUG [_VfsClient.py root _login (54)]: Logging in with email: zoe.connick@gmail.com
[2023-05-14 13:03:21,927] DEBUG [_VfsClient.py root _validate_login (75)]: Logged in successfully
[2023-05-14 13:03:21,929] INFO [_VfsClient.py root _get_appointment_date (81)]: Getting appointment date: Visa Centre: Portugal Visa application Centre London, Category: National Visa, Sub-Category: Long Stay
[2023-05-14 13:05:09,409] INFO [vfs_appointment_bot.py __main__ <module> (49)]: Unable to locate element: //html/body/app-root/div/app-dashboard/section[1]/div/div[2]/button. Please check the logs for more details
[2023-05-14 13:05:09,414] DEBUG [vfs_appointment_bot.py __main__ <module> (50)]: Message: Unable to locate element: //html/body/app-root/div/app-dashboard/section[1]/div/div[2]/button
Traceback (most recent call last):
  File "/Users/kennethyellow/Documents/yellow/vfs-appointment-bot/vfs_appointment_bot/vfs_appointment_bot.py", line 45, in <module>
    _vfs_client.check_slot(visa_centre=visa_centre, category=category, sub_category=sub_category)
  File "/Users/kennethyellow/Documents/yellow/vfs-appointment-bot/vfs_appointment_bot/_VfsClient.py", line 154, in check_slot
    _message = self._get_appointment_date(visa_centre, category, sub_category)
  File "/Users/kennethyellow/Documents/yellow/vfs-appointment-bot/vfs_appointment_bot/_VfsClient.py", line 83, in _get_appointment_date
    _new_booking_button = self._web_driver.find_element_by_xpath(
  File "/Users/kennethyellow/Documents/yellow/vfs-appointment-bot/venv/lib/python3.9/site-packages/selenium/webdriver/remote/webdriver.py", line 394, in find_element_by_xpath
    return self.find_element(by=By.XPATH, value=xpath)
  File "/Users/kennethyellow/Documents/yellow/vfs-appointment-bot/venv/lib/python3.9/site-packages/selenium/webdriver/remote/webdriver.py", line 976, in find_element
    return self.execute(Command.FIND_ELEMENT, {
  File "/Users/kennethyellow/Documents/yellow/vfs-appointment-bot/venv/lib/python3.9/site-packages/selenium/webdriver/remote/webdriver.py", line 321, in execute
    self.error_handler.check_response(response)
  File "/Users/kennethyellow/Documents/yellow/vfs-appointment-bot/venv/lib/python3.9/site-packages/selenium/webdriver/remote/errorhandler.py", line 242, in check_response
    raise exception_class(message, screen, stacktrace)
selenium.common.exceptions.NoSuchElementException: Message: Unable to locate element: //html/body/app-root/div/app-dashboard/section[1]/div/div[2]/button
Stack (most recent call last):
  File "/Users/kennethyellow/Library/Application Support/JetBrains/Toolbox/apps/PyCharm-P/ch-0/231.8109.197/PyCharm.app/Contents/plugins/python/helpers/pydev/pydevd.py", line 2195, in <module>
    main()
  File "/Users/kennethyellow/Library/Application Support/JetBrains/Toolbox/apps/PyCharm-P/ch-0/231.8109.197/PyCharm.app/Contents/plugins/python/helpers/pydev/pydevd.py", line 2177, in main
    globals = debugger.run(setup['file'], None, None, is_module)
  File "/Users/kennethyellow/Library/Application Support/JetBrains/Toolbox/apps/PyCharm-P/ch-0/231.8109.197/PyCharm.app/Contents/plugins/python/helpers/pydev/pydevd.py", line 1489, in run
    return self._exec(is_module, entry_point_fn, module_name, file, globals, locals)
  File "/Users/kennethyellow/Library/Application Support/JetBrains/Toolbox/apps/PyCharm-P/ch-0/231.8109.197/PyCharm.app/Contents/plugins/python/helpers/pydev/pydevd.py", line 1496, in _exec
    pydev_imports.execfile(file, globals, locals)  # execute the script
  File "/Users/kennethyellow/Library/Application Support/JetBrains/Toolbox/apps/PyCharm-P/ch-0/231.8109.197/PyCharm.app/Contents/plugins/python/helpers/pydev/_pydev_imps/_pydev_execfile.py", line 18, in execfile
    exec(compile(contents+"\n", file, 'exec'), glob, loc)
  File "/Users/kennethyellow/Documents/yellow/vfs-appointment-bot/vfs_appointment_bot/vfs_appointment_bot.py", line 50, in <module>
    logging.debug(e, exc_info=True, stack_info=True)
[2023-05-14 13:05:45,495] DEBUG [_ConfigReader.py root read_prop (13)]: twilio_to_num:to-number
[2023-05-14 13:05:45,495] DEBUG [_ConfigReader.py root read_prop (13)]: twilio_from_num:from-number
[2023-05-14 13:05:45,495] DEBUG [_ConfigReader.py root read_prop (13)]: twilio_account_sid:account-sid
[2023-05-14 13:05:45,495] DEBUG [_ConfigReader.py root read_prop (13)]: twilio_auth_token:auth-token
[2023-05-14 13:05:45,495] DEBUG [_ConfigReader.py root read_prop (13)]: twilio_url:twilio-url
[2023-05-14 13:05:45,495] DEBUG [_ConfigReader.py root read_bool_prop (18)]: twilio_sms_enabled:True
[2023-05-14 13:05:45,495] DEBUG [_ConfigReader.py root read_bool_prop (18)]: twilio_call_enabled:True
[2023-05-14 13:05:45,496] DEBUG [_ConfigReader.py root read_prop (13)]: chat_id:-1001941267897
[2023-05-14 13:05:45,496] DEBUG [_ConfigReader.py root read_prop (13)]: parse_mode:Markdown
[2023-05-14 13:05:45,496] DEBUG [_ConfigReader.py root read_prop (13)]: bot_token:6281742980:AAGIAXJlxLQhzvW4oveGtq9Y7bUxfXyf0Wc
[2023-05-14 13:05:45,496] DEBUG [_ConfigReader.py root read_prop (13)]: use_telegram:True
[2023-05-14 13:05:45,496] DEBUG [_ConfigReader.py root read_prop (13)]: use_twilio:False
[2023-05-14 13:05:45,496] DEBUG [_VfsClient.py root __init__ (25)]: Will use Telegram : True
[2023-05-14 13:05:45,496] DEBUG [_VfsClient.py root __init__ (26)]: Will use Twilio : False
[2023-05-14 13:05:45,496] DEBUG [_ConfigReader.py root read_prop (13)]: interval:120
[2023-05-14 13:05:45,496] DEBUG [vfs_appointment_bot.py __main__ <module> (37)]: Interval: 120
[2023-05-14 13:05:55,404] DEBUG [vfs_appointment_bot.py __main__ _input (19)]: Visa centre: Portugal Visa application Centre London, Category: Long Stay, Sub-Category: National Visa
[2023-05-14 13:05:55,405] INFO [vfs_appointment_bot.py __main__ <module> (41)]: Starting VFS Appointment Bot
[2023-05-14 13:05:55,405] INFO [vfs_appointment_bot.py __main__ <module> (44)]: Running VFS Appointment Bot: Attempt#1
[2023-05-14 13:05:57,358] DEBUG [_ConfigReader.py root read_prop (13)]: vfs_login_url:https://visa.vfsglobal.com/gbr/en/prt/login
[2023-05-14 13:05:58,134] DEBUG [_ConfigReader.py root read_prop (13)]: vfs_email:zoe.connick@gmail.com
[2023-05-14 13:05:58,134] DEBUG [_ConfigReader.py root read_prop (13)]: vfs_password:Password1!2
[2023-05-14 13:05:58,134] DEBUG [_VfsClient.py root _login (54)]: Logging in with email: zoe.connick@gmail.com
[2023-05-14 13:06:18,478] DEBUG [_VfsClient.py root _validate_login (75)]: Logged in successfully
[2023-05-14 13:06:18,479] INFO [_VfsClient.py root _get_appointment_date (81)]: Getting appointment date: Visa Centre: Portugal Visa application Centre London, Category: Long Stay, Sub-Category: National Visa
[2023-05-14 13:06:30,750] INFO [vfs_appointment_bot.py __main__ <module> (49)]: Unable to locate element: //html/body/app-root/div/app-dashboard/section[1]/div/div[2]/button/span[1]. Please check the logs for more details
[2023-05-14 13:06:30,755] DEBUG [vfs_appointment_bot.py __main__ <module> (50)]: Message: Unable to locate element: //html/body/app-root/div/app-dashboard/section[1]/div/div[2]/button/span[1]
Traceback (most recent call last):
  File "/Users/kennethyellow/Documents/yellow/vfs-appointment-bot/vfs_appointment_bot/vfs_appointment_bot.py", line 45, in <module>
    _vfs_client.check_slot(visa_centre=visa_centre, category=category, sub_category=sub_category)
  File "/Users/kennethyellow/Documents/yellow/vfs-appointment-bot/vfs_appointment_bot/_VfsClient.py", line 154, in check_slot
    _message = self._get_appointment_date(visa_centre, category, sub_category)
  File "/Users/kennethyellow/Documents/yellow/vfs-appointment-bot/vfs_appointment_bot/_VfsClient.py", line 83, in _get_appointment_date
    _new_booking_button = self._web_driver.find_element_by_xpath(
  File "/Users/kennethyellow/Documents/yellow/vfs-appointment-bot/venv/lib/python3.9/site-packages/selenium/webdriver/remote/webdriver.py", line 394, in find_element_by_xpath
    return self.find_element(by=By.XPATH, value=xpath)
  File "/Users/kennethyellow/Documents/yellow/vfs-appointment-bot/venv/lib/python3.9/site-packages/selenium/webdriver/remote/webdriver.py", line 976, in find_element
    return self.execute(Command.FIND_ELEMENT, {
  File "/Users/kennethyellow/Documents/yellow/vfs-appointment-bot/venv/lib/python3.9/site-packages/selenium/webdriver/remote/webdriver.py", line 321, in execute
    self.error_handler.check_response(response)
  File "/Users/kennethyellow/Documents/yellow/vfs-appointment-bot/venv/lib/python3.9/site-packages/selenium/webdriver/remote/errorhandler.py", line 242, in check_response
    raise exception_class(message, screen, stacktrace)
selenium.common.exceptions.NoSuchElementException: Message: Unable to locate element: //html/body/app-root/div/app-dashboard/section[1]/div/div[2]/button/span[1]
Stack (most recent call last):
  File "/Users/kennethyellow/Library/Application Support/JetBrains/Toolbox/apps/PyCharm-P/ch-0/231.8109.197/PyCharm.app/Contents/plugins/python/helpers/pydev/pydevd.py", line 2195, in <module>
    main()
  File "/Users/kennethyellow/Library/Application Support/JetBrains/Toolbox/apps/PyCharm-P/ch-0/231.8109.197/PyCharm.app/Contents/plugins/python/helpers/pydev/pydevd.py", line 2177, in main
    globals = debugger.run(setup['file'], None, None, is_module)
  File "/Users/kennethyellow/Library/Application Support/JetBrains/Toolbox/apps/PyCharm-P/ch-0/231.8109.197/PyCharm.app/Contents/plugins/python/helpers/pydev/pydevd.py", line 1489, in run
    return self._exec(is_module, entry_point_fn, module_name, file, globals, locals)
  File "/Users/kennethyellow/Library/Application Support/JetBrains/Toolbox/apps/PyCharm-P/ch-0/231.8109.197/PyCharm.app/Contents/plugins/python/helpers/pydev/pydevd.py", line 1496, in _exec
    pydev_imports.execfile(file, globals, locals)  # execute the script
  File "/Users/kennethyellow/Library/Application Support/JetBrains/Toolbox/apps/PyCharm-P/ch-0/231.8109.197/PyCharm.app/Contents/plugins/python/helpers/pydev/_pydev_imps/_pydev_execfile.py", line 18, in execfile
    exec(compile(contents+"\n", file, 'exec'), glob, loc)
  File "/Users/kennethyellow/Documents/yellow/vfs-appointment-bot/vfs_appointment_bot/vfs_appointment_bot.py", line 50, in <module>
    logging.debug(e, exc_info=True, stack_info=True)
[2023-05-14 13:08:11,801] DEBUG [_ConfigReader.py root read_prop (13)]: twilio_to_num:to-number
[2023-05-14 13:08:11,802] DEBUG [_ConfigReader.py root read_prop (13)]: twilio_from_num:from-number
[2023-05-14 13:08:11,802] DEBUG [_ConfigReader.py root read_prop (13)]: twilio_account_sid:account-sid
[2023-05-14 13:08:11,802] DEBUG [_ConfigReader.py root read_prop (13)]: twilio_auth_token:auth-token
[2023-05-14 13:08:11,802] DEBUG [_ConfigReader.py root read_prop (13)]: twilio_url:twilio-url
[2023-05-14 13:08:11,802] DEBUG [_ConfigReader.py root read_bool_prop (18)]: twilio_sms_enabled:True
[2023-05-14 13:08:11,802] DEBUG [_ConfigReader.py root read_bool_prop (18)]: twilio_call_enabled:True
[2023-05-14 13:08:11,802] DEBUG [_ConfigReader.py root read_prop (13)]: chat_id:-1001941267897
[2023-05-14 13:08:11,802] DEBUG [_ConfigReader.py root read_prop (13)]: parse_mode:Markdown
[2023-05-14 13:08:11,802] DEBUG [_ConfigReader.py root read_prop (13)]: bot_token:6281742980:AAGIAXJlxLQhzvW4oveGtq9Y7bUxfXyf0Wc
[2023-05-14 13:08:11,802] DEBUG [_ConfigReader.py root read_prop (13)]: use_telegram:True
[2023-05-14 13:08:11,803] DEBUG [_ConfigReader.py root read_prop (13)]: use_twilio:False
[2023-05-14 13:08:11,803] DEBUG [_VfsClient.py root __init__ (25)]: Will use Telegram : True
[2023-05-14 13:08:11,803] DEBUG [_VfsClient.py root __init__ (26)]: Will use Twilio : False
[2023-05-14 13:08:11,803] DEBUG [_ConfigReader.py root read_prop (13)]: interval:120
[2023-05-14 13:08:11,803] DEBUG [vfs_appointment_bot.py __main__ <module> (37)]: Interval: 120
[2023-05-14 13:08:29,294] DEBUG [vfs_appointment_bot.py __main__ _input (19)]: Visa centre: Portugal Visa application Centre London, Category: National Visa, Sub-Category: Long Stay
[2023-05-14 13:08:29,294] INFO [vfs_appointment_bot.py __main__ <module> (41)]: Starting VFS Appointment Bot
[2023-05-14 13:08:29,294] INFO [vfs_appointment_bot.py __main__ <module> (44)]: Running VFS Appointment Bot: Attempt#1
[2023-05-14 13:08:31,249] DEBUG [_ConfigReader.py root read_prop (13)]: vfs_login_url:https://visa.vfsglobal.com/gbr/en/prt/login
[2023-05-14 13:08:31,972] DEBUG [_ConfigReader.py root read_prop (13)]: vfs_email:zoe.connick@gmail.com
[2023-05-14 13:08:31,972] DEBUG [_ConfigReader.py root read_prop (13)]: vfs_password:Password1!2
[2023-05-14 13:08:31,972] DEBUG [_VfsClient.py root _login (54)]: Logging in with email: zoe.connick@gmail.com
[2023-05-14 13:08:52,312] DEBUG [_VfsClient.py root _validate_login (75)]: Logged in successfully
[2023-05-14 13:08:52,314] INFO [_VfsClient.py root _get_appointment_date (81)]: Getting appointment date: Visa Centre: Portugal Visa application Centre London, Category: National Visa, Sub-Category: Long Stay
[2023-05-14 13:10:32,695] DEBUG [_ConfigReader.py root read_prop (13)]: twilio_to_num:to-number
[2023-05-14 13:10:32,695] DEBUG [_ConfigReader.py root read_prop (13)]: twilio_from_num:from-number
[2023-05-14 13:10:32,695] DEBUG [_ConfigReader.py root read_prop (13)]: twilio_account_sid:account-sid
[2023-05-14 13:10:32,695] DEBUG [_ConfigReader.py root read_prop (13)]: twilio_auth_token:auth-token
[2023-05-14 13:10:32,695] DEBUG [_ConfigReader.py root read_prop (13)]: twilio_url:twilio-url
[2023-05-14 13:10:32,695] DEBUG [_ConfigReader.py root read_bool_prop (18)]: twilio_sms_enabled:True
[2023-05-14 13:10:32,695] DEBUG [_ConfigReader.py root read_bool_prop (18)]: twilio_call_enabled:True
[2023-05-14 13:10:32,696] DEBUG [_ConfigReader.py root read_prop (13)]: chat_id:-1001941267897
[2023-05-14 13:10:32,696] DEBUG [_ConfigReader.py root read_prop (13)]: parse_mode:Markdown
[2023-05-14 13:10:32,696] DEBUG [_ConfigReader.py root read_prop (13)]: bot_token:6281742980:AAGIAXJlxLQhzvW4oveGtq9Y7bUxfXyf0Wc
[2023-05-14 13:10:32,696] DEBUG [_ConfigReader.py root read_prop (13)]: use_telegram:True
[2023-05-14 13:10:32,696] DEBUG [_ConfigReader.py root read_prop (13)]: use_twilio:False
[2023-05-14 13:10:32,696] DEBUG [_VfsClient.py root __init__ (25)]: Will use Telegram : True
[2023-05-14 13:10:32,696] DEBUG [_VfsClient.py root __init__ (26)]: Will use Twilio : False
[2023-05-14 13:10:32,696] DEBUG [_ConfigReader.py root read_prop (13)]: interval:120
[2023-05-14 13:10:32,696] DEBUG [vfs_appointment_bot.py __main__ <module> (37)]: Interval: 120
[2023-05-14 13:11:00,196] DEBUG [vfs_appointment_bot.py __main__ _input (19)]: Visa centre: Portugal Visa application Centre London, Category: Long Stay, Sub-Category: National Visa
[2023-05-14 13:11:00,197] INFO [vfs_appointment_bot.py __main__ <module> (41)]: Starting VFS Appointment Bot
[2023-05-14 13:11:00,197] INFO [vfs_appointment_bot.py __main__ <module> (44)]: Running VFS Appointment Bot: Attempt#1
[2023-05-14 13:11:02,155] DEBUG [_ConfigReader.py root read_prop (13)]: vfs_login_url:https://visa.vfsglobal.com/gbr/en/prt/login
[2023-05-14 13:11:02,917] DEBUG [_ConfigReader.py root read_prop (13)]: vfs_email:zoe.connick@gmail.com
[2023-05-14 13:11:02,917] DEBUG [_ConfigReader.py root read_prop (13)]: vfs_password:Password1!2
[2023-05-14 13:11:02,917] DEBUG [_VfsClient.py root _login (54)]: Logging in with email: zoe.connick@gmail.com
[2023-05-14 13:11:34,598] DEBUG [_VfsClient.py root _validate_login (75)]: Logged in successfully
[2023-05-14 13:11:34,599] INFO [_VfsClient.py root _get_appointment_date (81)]: Getting appointment date: Visa Centre: Portugal Visa application Centre London, Category: Long Stay, Sub-Category: National Visa
